Workbook

Sheet Summary
A1: V-A Portfolio Analysis — Vanessa Pepino Adraneda
A2: Sources: E*TRADE SEP IRA statement Aug 2026; Robinhood statement Jul 2026; E*TRADE individual statement Jun 2020 (C:\WAN\V-A). Blue = transcribed input; black = formula; green = link to another sheet.
A4: Account snapshot | B4: SEP IRA (8/31/26) | C4: Robinhood (7/31/26) | D4: Combined | E4: Note
A5: Securities market value | B5: ='SEP IRA'!H42 -> 238206.56 | C5: =Robinhood!F58 -> 437464.08 | D5: =B5+C5 -> 675670.64 | E5: Robinhood value is one month older than the SEP IRA
A6: Cash / (margin debit) | B6: ='SEP IRA'!B48 -> 16443.72 | C6: =Robinhood!O14 -> -216910.5 | D6: =B6+C6 -> -200466.78 | E6: Robinhood cash is a margin loan (negative)
A7: Net account value (equity) | B7: =B5+B6 -> 254650.28 | C7: =C5+C6 -> 220553.58 | D7: =B7+C7 -> 475203.86
A8: Leverage: securities ÷ equity | B8: =B5/B7 -> 0.93542626 | C8: =C5/C7 -> 1.9834821 | D8: =D5/D7 -> 1.4218543 | E8: 1.00x = unlevered
A9: Number of positions | B9: =COUNTA('SEP IRA'!A8:A40) -> 33 | C9: =COUNTA(Robinhood!A9:A56) -> 48
A10: Top-10 holdings share of securities | B10: ='SEP IRA'!I44 -> 0.64187699 | C10: =Robinhood!H59 -> 0.64877445
A11: Effective number of holdings (1/HHI) | B11: ='SEP IRA'!I45 -> 15.340612 | C11: =Robinhood!H60 -> 16.164433 | E11: Higher = more evenly spread
A12: Estimated annual income | B12: ='SEP IRA'!K42 -> 6959.12 | C12: =Robinhood!G58 -> 2730.88 | D12: =B12+C12 -> 9690 | E12: SEP figure inflated by option-income ETF distributions
A15: Performance | B15: SEP IRA | C15: Robinhood | E15: Note
A16: Period covered | B16: Jan–Aug 2026 (YTD) and Aug 2026 | C16: Jul 2026 only
A17: Beginning value (period) | B17: ='SEP IRA'!B49 -> 214568.04 | C17: =Robinhood!O9 -> 237113.93 | E17: SEP: 1 Jan 2026 fair market value; RH: 1 Jul 2026 portfolio value
A18: External deposits (+) / withdrawals (−) | B18: ='SEP IRA'!B50 -> 50000 | C18: =Robinhood!O18 -> 6.98 | E18: SEP: $50,000 employer SEP contribution 2026 YTD; RH: $6.98 transfer from spending
A19: Dividends & interest received | B19: ='SEP IRA'!B51 -> 4140.66 | C19: =Robinhood!O15 -> 446.58
A20: Margin interest paid | B20: 0 | C20: =-Robinhood!O17 -> -731.94 | E20: SEP IRA has no margin
A21: Change in value (investment gain/loss) | B21: ='SEP IRA'!B52 -> -9917.76 | C21: =Robinhood!O25 -> -16567.33 | E21: Includes income; RH figure is net of margin interest
A22: Ending value (period) | B22: ='SEP IRA'!B53 -> 254650.28 | C22: =Robinhood!O10 -> 220553.58
A23: Return, Modified Dietz (flows at mid-period) | B23: ='SEP IRA'!B54 -> -0.04139851 | C23: =Robinhood!O26 -> -0.06986973 | E23: SEP: −3.7% if the $50k arrived 1 Jan, −4.6% if 31 Aug
A24: Realized gain/(loss), period | B24: ='SEP IRA'!B55 -> -9503.93 | C24: n/a | E24: Robinhood statement carries no cost basis
A25: Unrealized gain/(loss) at period end | B25: ='SEP IRA'!I42 -> 55863.56 | C25: n/a
A28: Method notes
A29: Every figure in blue was transcribed from the statement PDFs and independently re-checked; position tables reconcile to the statements' printed totals to the cent.
A30: Modified Dietz return = gain ÷ (beginning value + ½ × net external flows). The SEP IRA's $50,000 2026 contribution date is not shown on the August statement, so mid-year weighting is an assumption.
A31: Robinhood's 'Portfolio Value' is equity after the margin loan; returns on gross securities are shown on the Robinhood sheet. Robinhood prints no cost basis, so per-position gains are only available for the SEP IRA.
A32: The June 2020 E*TRADE statement is the opening month of an earlier individual account (4754-9228); it is included as a historical snapshot only and cannot be linked to the 2026 accounts.
A33: Household additions (15 Sep 2026)
A34: Luke UTMA value 31 Aug 2026 | B34: ='Luke UTMA'!P12 -> 107856.89
A35: UTMA 2026 YTD return (Dietz) | B35: ='Luke UTMA'!P13 -> -0.0011128872
A36: Total cash & CD (all accounts) | B36: ='Cash & banking'!D11 -> 310474.01
A37: Cash earning ~0% | B37: ='Cash & banking'!D27 -> 203237.41
A38: Household net assets (SEP + RH equity + UTMA + bank cash/CD) | B38: =D7+'Luke UTMA'!P12+SUM('Cash & banking'!D5:D8) -> 855009.84
A39: Margin loan remaining after applying cash | B39: ='Cash & banking'!D32 -> 19473.981

Sheet SEP IRA
A1: E*TRADE from Morgan Stanley — SEP IRA 459-855137-203
A2: Statement for August 1–31, 2026 · Self-directed · Objective: Capital Appreciation · Beneficiary: Vanessa Adraneda Living Trust
A7: Symbol | B7: Security | C7: Kind | D7: Theme | E7: Quantity | F7: Price | G7: Total cost | H7: Market value | I7: Unrealized G/L | J7: Unrl % | K7: Est. annual income | L7: % of account | N7: Account summary | O7: Aug 2026 | P7: 2026 YTD
A8: GOOGL | B8: Alphabet Inc Cl A | C8: Stock | D8: Mega-cap tech | E8: 30 | F8: 339.35 | G8: 6734.45 | H8: 10180.5 | I8: 3446.05 | J8: =IF(G8=0,0,I8/G8) -> 0.51170474 | K8: 26.4 | L8: =H8/$B$53 -> 0.039978358 | N8: Beginning value | O8: 232750.22 | P8: 214568.04
A9: AMZN | B9: Amazon.com | C9: Stock | D9: Mega-cap tech | E9: 40 | F9: 259.77 | G9: 9269.55 | H9: 10390.8 | I9: 1121.25 | J9: =IF(G9=0,0,I9/G9) -> 0.12096056 | K9: 0 | L9: =H9/$B$53 -> 0.040804196 | N9: Contributions (employer SEP) | O9: 0 | P9: 50000
A10: APLD | B10: Applied Digital | C10: Stock | D10: AI infrastructure | E10: 260 | F10: 25.41 | G10: 4199.61 | H10: 6606.6 | I10: 2406.99 | J10: =IF(G10=0,0,I10/G10) -> 0.57314608 | K10: 0 | L10: =H10/$B$53 -> 0.025943816 | N10: Dividends & interest | O10: 416.43 | P10: 4140.66
A11: CELH | B11: Celsius Holdings | C11: Stock | D11: Consumer | E11: 150 | F11: 31.45 | G11: 4746.25 | H11: 4717.5 | I11: -28.75 | J11: =IF(G11=0,0,I11/G11) -> -0.0060574137 | K11: 0 | L11: =H11/$B$53 -> 0.018525407 | N11: Change in value (incl. income) | O11: 21900.06 | P11: -9917.76
A12: KO | B12: Coca-Cola | C12: Stock | D12: Consumer | E12: 100 | F12: 88.67 | G12: 6747.16 | H12: 8867 | I12: 2119.84 | J12: =IF(G12=0,0,I12/G12) -> 0.31418256 | K12: 212 | L12: =H12/$B$53 -> 0.034820303 | N12: Ending value | O12: =O8+O9+O11 -> 254650.28 | P12: =P8+P9+P11 -> 254650.28
A13: COIN | B13: Coinbase Global | C13: Stock | D13: Crypto / fintech | E13: 12 | F13: 188.12 | G13: 3429.23 | H13: 2257.44 | I13: -1171.79 | J13: =IF(G13=0,0,I13/G13) -> -0.34170645 | K13: 0 | L13: =H13/$B$53 -> 0.0088648636 | N13: Return (Modified Dietz, flows mid-period) | O13: =O11/(O8+O9/2) -> 0.094092543 | P13: =P11/(P8+P9/2) -> -0.04139851
A14: HIMS | B14: Hims & Hers Health | C14: Stock | D14: Healthcare | E14: 130 | F14: 29.58 | G14: 5495 | H14: 3845.4 | I14: -1649.6 | J14: =IF(G14=0,0,I14/G14) -> -0.30020018 | K14: 0 | L14: =H14/$B$53 -> 0.01510071 | N14: Realized gain/(loss) | O14: -5900.89 | P14: -9503.93
A15: IBM | B15: IBM | C15: Stock | D15: Mega-cap tech | E15: 20 | F15: 233.87 | G15: 6400.4 | H15: 4677.4 | I15: -1723 | J15: =IF(G15=0,0,I15/G15) -> -0.26920192 | K15: 135.2 | L15: =H15/$B$53 -> 0.018367936 | N15: Securities purchased | O15: -9733.23 | P15: -65364.4
A16: LOW | B16: Lowe's | C16: Stock | D16: Consumer | E16: 7 | F16: 204.7 | G16: 1544.54 | H16: 1432.9 | I16: -111.64 | J16: =IF(G16=0,0,I16/G16) -> -0.07228042 | K16: 35 | L16: =H16/$B$53 -> 0.0056269327 | N16: Securities sold | O16: 24245.34 | P16: 27543.59
A17: META | B17: Meta Platforms | C17: Stock | D17: Mega-cap tech | E17: 15 | F17: 572.34 | G17: 9080.11 | H17: 8585.1 | I17: -495.01 | J17: =IF(G17=0,0,I17/G17) -> -0.054515859 | K17: 31.5 | L17: =H17/$B$53 -> 0.033713295 | N17: Closing cash (bank deposit program, net of $55.68 debit) | O17: 16443.72 | P17: 16443.72
A18: MU | B18: Micron Technology | C18: Stock | D18: Semiconductors | E18: 5 | F18: 958.73 | G18: 4612.3 | H18: 4793.65 | I18: 181.35 | J18: =IF(G18=0,0,I18/G18) -> 0.039318778 | K18: 3 | L18: =H18/$B$53 -> 0.018824444
A19: NBIS | B19: Nebius Group | C19: Stock | D19: AI infrastructure | E19: 70 | F19: 206.32 | G19: 3232 | H19: 14442.4 | I19: 11210.4 | J19: =IF(G19=0,0,I19/G19) -> 3.4685644 | K19: 0 | L19: =H19/$B$53 -> 0.056714644
A20: NVDA | B20: NVIDIA | C20: Stock | D20: Semiconductors | E20: 25 | F20: 220.78 | G20: 3222.75 | H20: 5519.5 | I20: 2296.75 | J20: =IF(G20=0,0,I20/G20) -> 0.71266775 | K20: 25 | L20: =H20/$B$53 -> 0.021674824
A21: OKLO | B21: Oklo Inc | C21: Stock | D21: Nuclear / uranium | E21: 300 | F21: 40.57 | G21: 9938.24 | H21: 12171 | I21: 2232.76 | J21: =IF(G21=0,0,I21/G21) -> 0.22466352 | K21: 0 | L21: =H21/$B$53 -> 0.04779496
A22: ONDS | B22: Ondas Inc | C22: Stock | D22: Drones / space | E22: 100 | F22: 7.655 | G22: 864 | H22: 765.5 | I22: -98.5 | J22: =IF(G22=0,0,I22/G22) -> -0.11400463 | K22: 0 | L22: =H22/$B$53 -> 0.0030060835
A23: OSCR | B23: Oscar Health | C23: Stock | D23: Healthcare | E23: 200 | F23: 29.96 | G23: 2800 | H23: 5992 | I23: 3192 | J23: =IF(G23=0,0,I23/G23) -> 1.14 | K23: 0 | L23: =H23/$B$53 -> 0.02353031
A24: PLTR | B24: Palantir Technologies | C24: Stock | D24: Software / AI | E24: 60 | F24: 186.38 | G24: 5575.14 | H24: 11182.8 | I24: 5607.66 | J24: =IF(G24=0,0,I24/G24) -> 1.005833 | K24: 0 | L24: =H24/$B$53 -> 0.043914344
A25: PPTA | B25: Perpetua Resources | C25: Stock | D25: Metals / mining | E25: 150 | F25: 24.935 | G25: 1941 | H25: 3740.32 | I25: 1799.32 | J25: =IF(G25=0,0,I25/G25) -> 0.9270067 | K25: 0 | L25: =H25/$B$53 -> 0.014688066
A26: QSI | B26: Quantum-Si | C26: Stock | D26: Quantum / speculative | E26: 200 | F26: 0.766 | G26: 640 | H26: 153.18 | I26: -486.82 | J26: =IF(G26=0,0,I26/G26) -> -0.76065625 | K26: 0 | L26: =H26/$B$53 -> 0.00060153085
A27: RGTI | B27: Rigetti Computing | C27: Stock | D27: Quantum / speculative | E27: 125 | F27: 15.66 | G27: 1887.08 | H27: 1957.5 | I27: 70.42 | J27: =IF(G27=0,0,I27/G27) -> 0.037316913 | K27: 0 | L27: =H27/$B$53 -> 0.0076870129
A28: HOOD | B28: Robinhood Markets | C28: Stock | D28: Crypto / fintech | E28: 410 | F28: 104.81 | G28: 20272.51 | H28: 42972.1 | I28: 22699.59 | J28: =IF(G28=0,0,I28/G28) -> 1.1197227 | K28: 0 | L28: =H28/$B$53 -> 0.16874947
A29: RKLB | B29: Rocket Lab | C29: Stock | D29: Drones / space | E29: 100 | F29: 63.92 | G29: 8049.42 | H29: 6392 | I29: -1657.42 | J29: =IF(G29=0,0,I29/G29) -> -0.20590552 | K29: 0 | L29: =H29/$B$53 -> 0.025101092
... A40: NVDY | B40: YieldMax NVDA Option Income ETF | C40: ETF | D40: Option-income ETF | E40: 600 | F40: 12.66 | G40: 9379.35 | H40: 7596 | I40: -1783.35 | J40: =IF(G40=0,0,I40/G40) -> -0.19013578 | K40: 4332.6 | L40: =H40/$B$53 -> 0.029829145
B42: Total securities | G42: =SUM(G8:G40) -> 182343 | H42: =SUM(H8:H40) -> 238206.56 | I42: =SUM(I8:I40) -> 55863.56 | J42: =I42/G42 -> 0.30636526 | K42: =SUM(K8:K40) -> 6959.12 | L42: =SUM(L8:L40) -> 0.93542626
B43: Statement check: stocks $187,129.00 + ETFs $51,077.56 = $238,206.56; unrealized $55,863.56; cost $182,343.00
B44: Top-10 holdings share of securities | I44: =SUMPRODUCT(LARGE(H8:H40,{1,2,3,4,5,6,7,8,9,10}))/H42 -> 0.64187699
B45: Effective number of holdings (1/HHI) | I45: =1/SUMPRODUCT((H8:H40/H42)^2) -> 15.340612
A47: Key figures (linked)
A48: Closing cash | B48: =P17 -> 16443.72
A49: Beginning value 2026 | B49: =P8 -> 214568.04
A50: External flows 2026 YTD | B50: =P9 -> 50000
A51: Dividends & interest 2026 YTD | B51: =P10 -> 4140.66
A52: Change in value 2026 YTD | B52: =P11 -> -9917.76
A53: Ending value 31 Aug 2026 | B53: =P12 -> 254650.28
A54: Return 2026 YTD (Dietz) | B54: =P13 -> -0.04139851
A55: Realized G/L 2026 YTD | B55: =P14 -> -9503.93
A57: Lifetime SEP contributions (statement 'Retirement Recap')
...

Sheet Robinhood
A1: Robinhood — Individual margin account 140450008
A2: Statement for July 1–31, 2026 · Robinhood Gold · no cost basis printed
A8: Symbol | B8: Security | C8: Theme | D8: Quantity | E8: Price | F8: Market value | G8: Est. annual dividend | H8: % of securities | I8: % of equity | N8: Account summary — July 2026 | O8: Amount
A9: AMZN | B9: Amazon | C9: Mega-cap tech | D9: 220 | E9: 271.58 | F9: 59747.6 | G9: 0 | H9: =F9/$F$58 -> 0.13657716 | I9: =F9/$O$10 -> 0.27089835 | N9: Opening portfolio value (equity), 1 Jul | O9: 237113.93
A10: BATRA | B10: Atlanta Braves Holdings A | C10: Consumer | D10: 50 | E10: 54.41 | F10: 2720.5 | G10: 0 | H10: =F10/$F$58 -> 0.0062187963 | I10: =F10/$O$10 -> 0.012334871 | N10: Closing portfolio value (equity), 31 Jul | O10: 220553.58
A11: BTBT | B11: Bit Digital | C11: Crypto / fintech | D11: 500 | E11: 1.31 | F11: 655 | G11: 0 | H11: =F11/$F$58 -> 0.0014972658 | I11: =F11/$O$10 -> 0.0029697999 | N11: Opening securities | O11: 437891.49
A12: CELH | B12: Celsius | C12: Consumer | D12: 100 | E12: 29.21 | F12: 2921 | G12: 0 | H12: =F12/$F$58 -> 0.0066771196 | I12: =F12/$O$10 -> 0.013243947 | N12: Closing securities | O12: 437464.08
A13: CVX | B13: Chevron | C13: Energy | D13: 102.25043 | E13: 196.83 | F13: 20125.95 | G13: 732.2 | H13: =F13/$F$58 -> 0.046005949 | I13: =F13/$O$10 -> 0.091251976 | N13: Opening margin debit | O13: -200777.56
A14: EOSE | B14: Eos Energy | C14: Clean energy / batteries | D14: 250 | E14: 3.38 | F14: 845 | G14: 0 | H14: =F14/$F$58 -> 0.0019315872 | I14: =F14/$O$10 -> 0.0038312686 | N14: Closing margin debit | O14: -216910.5
A15: EOSER | B15: Eos Energy Right | C15: Clean energy / batteries | D15: 250 | E15: 0.0065 | F15: 1.63 | G15: 0 | H15: =F15/$F$58 -> 3.7260202e-06 | I15: =F15/$O$10 -> 7.3904944e-06 | N15: Dividends received (July) | O15: 446.58
A16: ERO | B16: Ero Copper | C16: Metals / mining | D16: 100 | E16: 26.91 | F16: 2691 | G16: 0 | H16: =F16/$F$58 -> 0.0061513622 | I16: =F16/$O$10 -> 0.012201117 | N16: Dividends received (2026 YTD) | O16: 3676.77
A17: FLY | B17: Firefly Aerospace | C17: Drones / space | D17: 100 | E17: 20.33 | F17: 2033 | G17: 0 | H17: =F17/$F$58 -> 0.0046472387 | I17: =F17/$O$10 -> 0.0092177148 | N17: Margin interest charged (July) | O17: 731.94
A18: GLD | B18: SPDR Gold Trust | C18: Precious metals | D18: 0.279515 | E18: 371.54 | F18: 103.85 | G18: 0 | H18: =F18/$F$58 -> 0.00023739092 | I18: =F18/$O$10 -> 0.00047086064 | N18: Transfer in from spending account | O18: 6.98
A19: GLND | B19: Greenland Energy | C19: Nuclear / uranium | D19: 500 | E19: 2.27 | F19: 1135 | G19: 0 | H19: =F19/$F$58 -> 0.0025944987 | I19: =F19/$O$10 -> 0.0051461418 | N19: Robinhood Gold deposit boost | O19: 5.71
A20: GOOGL | B20: Alphabet Class A | C20: Mega-cap tech | D20: 171.30534 | E20: 356.13 | F20: 61006.97 | G20: 154.01 | H20: =F20/$F$58 -> 0.13945595 | I20: =F20/$O$10 -> 0.27660839 | N20: Securities purchased (incl. $424.41 dividend reinvestment) | O20: =SUMIF($B$67:$B$98,"Buy*",$G$67:$G$98) -> 15860.27
A21: HOOD | B21: Robinhood Markets | C21: Crypto / fintech | D21: 150 | E21: 86.56 | F21: 12984 | G21: 0 | H21: =F21/$F$58 -> 0.029680151 | I21: =F21/$O$10 -> 0.058870049 | N21: Check: change in margin debit = −purchases − interest + dividends + transfers | O21: =O14-O13 -> -16132.94
A22: IBM | B22: IBM | C22: Mega-cap tech | D22: 80 | E22: 223.65 | F22: 17892 | G22: 531.77 | H22: =F22/$F$58 -> 0.040899358 | I22: =F22/$O$10 -> 0.081123145 | N22: computed from activity | O22: =-O20-O17+O15+O18+O19 -> -16132.94
A23: IMSR | B23: Terrestrial Energy | C23: Nuclear / uranium | D23: 150 | E23: 4.91 | F23: 736.5 | G23: 0 | H23: =F23/$F$58 -> 0.0016835668 | I23: =F23/$O$10 -> 0.0033393246 | N23: Market change on holdings = Δsecurities − purchases | O23: =O12-O11-O20 -> -16287.68
A24: IONQ | B24: IonQ | C24: Quantum / speculative | D24: 200 | E24: 36.44 | F24: 7288 | G24: 0 | H24: =F24/$F$58 -> 0.016659654 | I24: =F24/$O$10 -> 0.033044125 | N24: Return on gross securities (market change + dividends) | O24: =(O23+O15)/O11 -> -0.036175857
A25: IREN | B25: IREN Limited | C25: AI infrastructure | D25: 50 | E25: 36.8 | F25: 1840 | G25: 0 | H25: =F25/$F$58 -> 0.0042060596 | I25: =F25/$O$10 -> 0.008342644 | N25: Change in equity (excl. transfer) | O25: =O10-O9-O18 -> -16567.33
A26: IWMI | B26: NEOS Russell 2000 High Income ETF | C26: Option-income ETF | D26: 114.68258 | E26: 51.7583 | F26: 5935.78 | G26: 0 | H26: =F26/$F$58 -> 0.013568611 | I26: =F26/$O$10 -> 0.026913097 | N26: Return on equity, July (Modified Dietz) | O26: =O25/(O9+O18/2) -> -0.06986973
A27: JD | B27: JD.com | C27: Consumer | D27: 103.27185 | E27: 33.01 | F27: 3409 | G27: 103.75 | H27: =F27/$F$58 -> 0.0077926398 | I27: =F27/$O$10 -> 0.015456562 | N27: Average margin debit | O27: =-(O13+O14)/2 -> 208844.03
A28: KO | B28: Coca-Cola | C28: Consumer | D28: 204.77904 | E28: 87.59 | F28: 17936.6 | G28: 418.82 | H28: =F28/$F$58 -> 0.041001309 | I28: =F28/$O$10 -> 0.081325363 | N28: Implied annual margin rate | O28: =O17*12/O27 -> 0.042056649
A29: LAC | B29: Lithium Americas | C29: Metals / mining | D29: 200 | E29: 2.87 | F29: 574 | G29: 0 | H29: =F29/$F$58 -> 0.0013121077 | I29: =F29/$O$10 -> 0.0026025422 | N29: Annualised margin cost at July's rate | O29: =O17*12 -> 8783.28
A30: LITE | B30: Lumentum | C30: AI infrastructure | D30: 10 | E30: 713.94 | F30: 7139.4 | G30: 0 | H30: =F30/$F$58 -> 0.016319968 | I30: =F30/$O$10 -> 0.032370366 | N30: Leverage: securities ÷ equity (31 Jul) | O30: =O12/O10 -> 1.9834821
A31: MSFT | B31: Microsoft | C31: Mega-cap tech | D31: 49.333799 | E31: 464.72 | F31: 22926.4 | G31: 208.99 | H31: =F31/$F$58 -> 0.052407503 | I31: =F31/$O$10 -> 0.10394934 | N31: Equity as % of securities | O31: =O10/O12 -> 0.50416386
A32: MU | B32: Micron Technology | C32: Semiconductors | D32: 15.002217 | E32: 823.03 | F32: 12347.27 | G32: 8.27 | H32: =F32/$F$58 -> 0.028224649 | I32: =F32/$O$10 -> 0.055983086 | N32: Maintenance requirement (assumption) | O32: 0.3
A33: NFLX | B33: Netflix | C33: Mega-cap tech | D33: 70 | E33: 71.71 | F33: 5019.7 | G33: 0 | H33: =F33/$F$58 -> 0.011474542 | I33: =F33/$O$10 -> 0.022759549 | N33: Market decline that would trigger a maintenance call | O33: =1-(-O14)/(O12*(1-O32)) -> 0.29166266
A34: NOW | B34: ServiceNow | C34: Software / AI | D34: 50 | E34: 111.23 | F34: 5561.5 | G34: 0 | H34: =F34/$F$58 -> 0.012713044 | I34: =F34/$O$10 -> 0.025216095
A35: NVDA | B35: NVIDIA | C35: Semiconductors | D35: 100 | E35: 200.75 | F35: 20075 | G35: 29.58 | H35: =F35/$F$58 -> 0.045889482 | I35: =F35/$O$10 -> 0.091020966
A36: NVTS | B36: Navitas Semiconductor | C36: Semiconductors | D36: 200 | E36: 10.86 | F36: 2172 | G36: 0 | H36: =F36/$F$58 -> 0.0049649791 | I36: =F36/$O$10 -> 0.0098479472
A37: ONDS | B37: Ondas Inc | C37: Drones / space | D37: 400 | E37: 7.49 | F37: 2996 | G37: 0 | H37: =F37/$F$58 -> 0.0068485623 | I37: =F37/$O$10 -> 0.013584001
A38: PCG | B38: PG&E | C38: Utilities | D38: 201.80657 | E38: 17.38 | F38: 3507.4 | G38: 34.66 | H38: =F38/$F$58 -> 0.0080175726 | I38: =F38/$O$10 -> 0.015902712
A39: QBTS | B39: D-Wave Quantum | C39: Quantum / speculative | D39: 200.37512 | E39: 18.08 | F39: 3622.78 | G39: 0 | H39: =F39/$F$58 -> 0.0082813199 | I39: =F39/$O$10 -> 0.01642585
A40: QQQI | B40: NEOS Nasdaq 100 High Income ETF | C40: Option-income ETF | D40: 535.44744 | E40: 53.04 | F40: 28400.13 | G40: 155.04 | H40: =F40/$F$58 -> 0.064919913 | I40: =F40/$O$10 -> 0.12876749
A41: QUBT | B41: Quantum Computing Inc | C41: Quantum / speculative | D41: 100 | E41: 8.1 | F41: 810 | G41: 0 | H41: =F41/$F$58 -> 0.0018515806 | I41: =F41/$O$10 -> 0.003672577
A42: RDW | B42: Redwire | C42: Drones / space | D42: 100 | E42: 8.62 | F42: 862 | G42: 0 | H42: =F42/$F$58 -> 0.0019704475 | I42: =F42/$O$10 -> 0.0039083474
A43: RGTI | B43: Rigetti Computing | C43: Quantum / speculative | D43: 500 | E43: 14.95 | F43: 7475 | G43: 0 | H43: =F43/$F$58 -> 0.017087117 | I43: =F43/$O$10 -> 0.033891991
A44: RKLB | B44: Rocket Lab | C44: Drones / space | D44: 100.16742 | E44: 64.95 | F44: 6505.87 | G44: 0 | H44: =F44/$F$58 -> 0.014871781 | I44: =F44/$O$10 -> 0.029497912
A45: SCHG | B45: Schwab US Large-Cap Growth ETF | C45: Index ETF | D45: 251.86384 | E45: 34.17 | F45: 8606.19 | G45: 36 | H45: =F45/$F$58 -> 0.019672907 | I45: =F45/$O$10 -> 0.039020858
...

Sheet Combined holdings
A1: Combined look-through — SEP IRA (8/31/26) + Robinhood (7/31/26)
A2: Same security held in both accounts is summed. Dates differ by one month.
A4: Symbol | B4: Security | C4: Theme | D4: SEP IRA | E4: Robinhood | F4: Combined | G4: % of combined
A5: GOOGL | B5: Alphabet Inc Cl A | C5: Mega-cap tech | D5: =SUMIF('SEP IRA'!$A$8:$A$40,A5,'SEP IRA'!$H$8:$H$40) -> 10180.5 | E5: =SUMIF(Robinhood!$A$9:$A$56,A5,Robinhood!$F$9:$F$56) -> 61006.97 | F5: =D5+E5 -> 71187.47 | G5: =F5/$F$69 -> 0.10535824
A6: AMZN | B6: Amazon.com | C6: Mega-cap tech | D6: =SUMIF('SEP IRA'!$A$8:$A$40,A6,'SEP IRA'!$H$8:$H$40) -> 10390.8 | E6: =SUMIF(Robinhood!$A$9:$A$56,A6,Robinhood!$F$9:$F$56) -> 59747.6 | F6: =D6+E6 -> 70138.4 | G6: =F6/$F$69 -> 0.10380561
A7: HOOD | B7: Robinhood Markets | C7: Crypto / fintech | D7: =SUMIF('SEP IRA'!$A$8:$A$40,A7,'SEP IRA'!$H$8:$H$40) -> 42972.1 | E7: =SUMIF(Robinhood!$A$9:$A$56,A7,Robinhood!$F$9:$F$56) -> 12984 | F7: =D7+E7 -> 55956.1 | G7: =F7/$F$69 -> 0.082815645
A8: SPYG | B8: SPDR Portfolio S&P 500 Growth ETF | C8: Index ETF | D8: =SUMIF('SEP IRA'!$A$8:$A$40,A8,'SEP IRA'!$H$8:$H$40) -> 18012.61 | E8: =SUMIF(Robinhood!$A$9:$A$56,A8,Robinhood!$F$9:$F$56) -> 19996.87 | F8: =D8+E8 -> 38009.48 | G8: =F8/$F$69 -> 0.05625445
A9: QQQI | B9: NEOS Nasdaq 100 High Income ETF | C9: Option-income ETF | D9: =SUMIF('SEP IRA'!$A$8:$A$40,A9,'SEP IRA'!$H$8:$H$40) -> 0 | E9: =SUMIF(Robinhood!$A$9:$A$56,A9,Robinhood!$F$9:$F$56) -> 28400.13 | F9: =D9+E9 -> 28400.13 | G9: =F9/$F$69 -> 0.042032506
A10: KO | B10: Coca-Cola | C10: Consumer | D10: =SUMIF('SEP IRA'!$A$8:$A$40,A10,'SEP IRA'!$H$8:$H$40) -> 8867 | E10: =SUMIF(Robinhood!$A$9:$A$56,A10,Robinhood!$F$9:$F$56) -> 17936.6 | F10: =D10+E10 -> 26803.6 | G10: =F10/$F$69 -> 0.039669624
A11: NVDA | B11: NVIDIA | C11: Semiconductors | D11: =SUMIF('SEP IRA'!$A$8:$A$40,A11,'SEP IRA'!$H$8:$H$40) -> 5519.5 | E11: =SUMIF(Robinhood!$A$9:$A$56,A11,Robinhood!$F$9:$F$56) -> 20075 | F11: =D11+E11 -> 25594.5 | G11: =F11/$F$69 -> 0.037880142
A12: MSFT | B12: Microsoft | C12: Mega-cap tech | D12: =SUMIF('SEP IRA'!$A$8:$A$40,A12,'SEP IRA'!$H$8:$H$40) -> 0 | E12: =SUMIF(Robinhood!$A$9:$A$56,A12,Robinhood!$F$9:$F$56) -> 22926.4 | F12: =D12+E12 -> 22926.4 | G12: =F12/$F$69 -> 0.033931325
A13: IBM | B13: IBM | C13: Mega-cap tech | D13: =SUMIF('SEP IRA'!$A$8:$A$40,A13,'SEP IRA'!$H$8:$H$40) -> 4677.4 | E13: =SUMIF(Robinhood!$A$9:$A$56,A13,Robinhood!$F$9:$F$56) -> 17892 | F13: =D13+E13 -> 22569.4 | G13: =F13/$F$69 -> 0.033402961
A14: CVX | B14: Chevron | C14: Energy | D14: =SUMIF('SEP IRA'!$A$8:$A$40,A14,'SEP IRA'!$H$8:$H$40) -> 0 | E14: =SUMIF(Robinhood!$A$9:$A$56,A14,Robinhood!$F$9:$F$56) -> 20125.95 | F14: =D14+E14 -> 20125.95 | G14: =F14/$F$69 -> 0.029786628
A15: MU | B15: Micron Technology | C15: Semiconductors | D15: =SUMIF('SEP IRA'!$A$8:$A$40,A15,'SEP IRA'!$H$8:$H$40) -> 4793.65 | E15: =SUMIF(Robinhood!$A$9:$A$56,A15,Robinhood!$F$9:$F$56) -> 12347.27 | F15: =D15+E15 -> 17140.92 | G15: =F15/$F$69 -> 0.025368751
A16: SPYI | B16: NEOS S&P 500 High Income ETF | C16: Option-income ETF | D16: =SUMIF('SEP IRA'!$A$8:$A$40,A16,'SEP IRA'!$H$8:$H$40) -> 16095 | E16: =SUMIF(Robinhood!$A$9:$A$56,A16,Robinhood!$F$9:$F$56) -> 0 | F16: =D16+E16 -> 16095 | G16: =F16/$F$69 -> 0.023820778
... A68: EOSER | B68: Eos Energy Right | C68: Clean energy / batteries | D68: =SUMIF('SEP IRA'!$A$8:$A$40,A68,'SEP IRA'!$H$8:$H$40) -> 0 | E68: =SUMIF(Robinhood!$A$9:$A$56,A68,Robinhood!$F$9:$F$56) -> 1.63 | F68: =D68+E68 -> 1.63 | G68: =F68/$F$69 -> 2.412418e-06
B69: Total securities | D69: =SUM(D5:D68) -> 238206.56 | E69: =SUM(E5:E68) -> 437464.08 | F69: =SUM(F5:F68) -> 675670.64
B70: Held in both accounts | F70: =SUMPRODUCT((D5:D68>0)*(E5:E68>0)) -> 17
B71: Top-10 share | F71: =SUMPRODUCT(LARGE(F5:F68,{1,2,3,4,5,6,7,8,9,10}))/F69 -> 0.56493713
B72: Effective number of holdings | F72: =1/SUMPRODUCT((F5:F68/F69)^2) -> 21.693804
B74: Exposure by theme
B75: Theme | F75: Combined | G75: %
B76: Mega-cap tech | F76: =SUMIF($C$5:$C$68,B76,$F$5:$F$68) -> 200426.47 | G76: =F76/$F$69 -> 0.29663339
B77: Index ETF | F77: =SUMIF($C$5:$C$68,B77,$F$5:$F$68) -> 68016.63 | G77: =F77/$F$69 -> 0.10066536
B78: Crypto / fintech | F78: =SUMIF($C$5:$C$68,B78,$F$5:$F$68) -> 62130.54 | G78: =F78/$F$69 -> 0.091953885
B79: Option-income ETF | F79: =SUMIF($C$5:$C$68,B79,$F$5:$F$68) -> 58026.91 | G79: =F79/$F$69 -> 0.085880467
B80: Consumer | F80: =SUMIF($C$5:$C$68,B80,$F$5:$F$68) -> 56447.68 | G80: =F80/$F$69 -> 0.083543189
B81: Semiconductors | F81: =SUMIF($C$5:$C$68,B81,$F$5:$F$68) -> 48040.82 | G81: =F81/$F$69 -> 0.071100944
B82: AI infrastructure | F82: =SUMIF($C$5:$C$68,B82,$F$5:$F$68) -> 30880.8 | G82: =F82/$F$69 -> 0.045703925
B83: Nuclear / uranium | F83: =SUMIF($C$5:$C$68,B83,$F$5:$F$68) -> 24775.51 | G83: =F83/$F$69 -> 0.036668028
B84: Software / AI | F84: =SUMIF($C$5:$C$68,B84,$F$5:$F$68) -> 24143.8 | G84: =F84/$F$69 -> 0.03573309
B85: Quantum / speculative | F85: =SUMIF($C$5:$C$68,B85,$F$5:$F$68) -> 21306.46 | G85: =F85/$F$69 -> 0.031533796
B86: Energy | F86: =SUMIF($C$5:$C$68,B86,$F$5:$F$68) -> 20125.95 | G86: =F86/$F$69 -> 0.029786628
B87: Drones / space | F87: =SUMIF($C$5:$C$68,B87,$F$5:$F$68) -> 19554.37 | G87: =F87/$F$69 -> 0.028940683
... B92: Clean energy / batteries | F92: =SUMIF($C$5:$C$68,B92,$F$5:$F$68) -> 846.63 | G92: =F92/$F$69 -> 0.0012530217

Sheet ETrade 2020
A1: E*TRADE individual account 4754-9228 — June 1–30, 2020 (opening month)
A2: Historical snapshot; account not present in the 2026 statements. Address at the time: Crown Point, IN.
A4: Symbol | B4: Security | C4: Quantity | D4: Price | E4: Market value | F4: Est. annual income | G4: % of account
A5: AMED | B5: Amedisys | C5: 10 | D5: 198.54 | E5: 1985.4 | F5: 0 | G5: =E5/$E$16 -> 0.17883425
A6: DG | B6: Dollar General | C6: 10 | D6: 190.51 | E6: 1905.1 | F6: 14 | G6: =E6/$E$16 -> 0.17160126
A7: ETSY | B7: Etsy | C7: 10 | D7: 106.23 | E7: 1062.3 | F7: 0 | G7: =E7/$E$16 -> 0.095686324
A8: GPS | B8: Gap | C8: 8 | D8: 12.62 | E8: 100.96 | F8: 0 | G8: =E8/$E$16 -> 0.0090939389
A9: MSFT | B9: Microsoft | C9: 10 | D9: 203.51 | E9: 2035.1 | F9: 20 | G9: =E9/$E$16 -> 0.18331096
A10: ROKU | B10: Roku | C10: 10 | D10: 116.53 | E10: 1165.3 | F10: 0 | G10: =E10/$E$16 -> 0.10496402
A11: SNE | B11: Sony ADR | C11: 10 | D11: 69.13 | E11: 691.3 | F11: 3 | G11: =E11/$E$16 -> 0.062268621
A12: SQ | B12: Square | C12: 9 | D12: 104.94 | E12: 944.46 | F12: 0 | G12: =E12/$E$16 -> 0.085071925
A13: WMT | B13: Walmart | C13: 10 | D13: 119.78 | E13: 1197.8 | F13: 22 | G13: =E13/$E$16 -> 0.10789144
B14: Total securities (statement $11,087.72) | E14: =SUM(E5:E13) -> 11087.72 | F14: =SUM(F5:F13) -> 59
B15: Cash (sweep) | E15: 14.18
B16: Net account value 6/30/20 (statement $11,101.90) | E16: =E14+E15 -> 11101.9
B18: Deposits in June 2020 | E18: =SUMIF(B22:B38,"Deposit",D22:D38) -> 11100
B19: Gain on deposits in first month | E19: =E16-E18 -> 1.9
A21: Date | B21: Type | C21: Description | D21: Amount
A22: 06/11 | B22: Deposit | C22: ACH deposit | D22: 1000
A23: 06/16 | B23: Bought | C23: VTI 6 @ 157.6451 | D23: -945.87
A24: 06/19 | B24: Deposit | C24: ACH deposit | D24: 10000
A25: 06/22 | B25: Bought | C25: MSFT 5 @ 199.8231 | D25: -999.12
A26: 06/22 | B26: Bought | C26: SNE 10 @ 71.71 | D26: -717.1
A27: 06/22 | B27: Sold | C27: VTI 6 @ 157.725 | D27: 946.32
A28: 06/24 | B28: Deposit | C28: ACH deposit | D28: 100
A29: 06/24 | B29: Bought | C29: AMED 3 @ 195.17 | D29: -585.51
A30: 06/24 | B30: Bought | C30: AMED 7 @ 195.4925 | D30: -1368.45
A31: 06/24 | B31: Bought | C31: DG 10 @ 189.9685 | D31: -1899.69
A32: 06/24 | B32: Bought | C32: ETSY 10 @ 99.88 | D32: -998.8
A33: 06/24 | B33: Bought | C33: MSFT 5 @ 201.255 | D33: -1006.28
... A38: 06/26 | B38: Interest | C38: Sweep interest | D38: 0.01
C39: Net = closing cash ($14.18) | D39: =SUM(D22:D38) -> 14.18

Sheet Luke UTMA
A1: E*TRADE custodial UTMA/IN 459-403795-201 — Luke Adraneda (until 21)
A2: Statement Aug 1–31 2026 · custodian Vanessa Pepino Adraneda · blue = transcribed, black = formula
A7: Symbol | B7: Security | C7: Kind | D7: Theme | E7: Quantity | F7: Price | G7: Total cost | H7: Market value | I7: Unrealized G/L | J7: Unrl % | K7: Est. annual income | L7: % of account | N7: Account summary | O7: Aug 2026 | P7: 2026 YTD
A8: GOOG | B8: Alphabet Inc Cl C | C8: Stock | D8: Mega-cap tech | E8: 51 | F8: 335.41 | G8: 8746.95 | H8: 17105.91 | I8: 8358.96 | J8: =IF(G8=0,0,I8/G8) -> 0.95564282 | K8: 44.88 | L8: =H8/$O$12 -> 0.15859821 | N8: Beginning value | O8: 99644.5 | P8: 97171.04
A9: AMZN | B9: Amazon.com | C9: Stock | D9: Mega-cap tech | E9: 4 | F9: 259.77 | G9: 1060.64 | H9: 1039.08 | I9: -21.56 | J9: =IF(G9=0,0,I9/G9) -> -0.02032735 | K9: 0 | L9: =H9/$O$12 -> 0.0096338769 | N9: Contributions (ACH deposits) | O9: 1350 | P9: 10800
A10: AAPL | B10: Apple | C10: Stock | D10: Mega-cap tech | E10: 30 | F10: 316.85 | G10: 3409.35 | H10: 9505.5 | I10: 6096.15 | J10: =IF(G10=0,0,I10/G10) -> 1.7880681 | K10: 32.4 | L10: =H10/$O$12 -> 0.08813067 | N10: Dividends & interest | O10: 152.27 | P10: 2458.4
A11: KO | B11: Coca-Cola | C11: Stock | D11: Consumer | E11: 77 | F11: 88.67 | G11: 4569.75 | H11: 6827.59 | I11: 2257.84 | J11: =IF(G11=0,0,I11/G11) -> 0.49408392 | K11: 163.24 | L11: =H11/$O$12 -> 0.063302307 | N11: Change in value (incl. income) | O11: 6862.39 | P11: -114.15
A12: INTC | B12: Intel | C12: Stock | D12: Semiconductors | E12: 10 | F12: 89.51 | G12: 1039.6 | H12: 895.1 | I12: -144.5 | J12: =IF(G12=0,0,I12/G12) -> -0.13899577 | K12: 0 | L12: =H12/$O$12 -> 0.0082989599 | N12: Ending value | O12: =O8+O9+O11 -> 107856.89 | P12: =P8+P9+P11 -> 107856.89
A13: IRM | B13: Iron Mountain | C13: Stock | D13: AI infrastructure | E13: 30 | F13: 115.35 | G13: 1251.52 | H13: 3460.5 | I13: 2208.98 | J13: =IF(G13=0,0,I13/G13) -> 1.7650377 | K13: 103.68 | L13: =H13/$O$12 -> 0.032084181 | N13: Return (Modified Dietz, flows mid-period) | O13: =O11/(O8+O9/2) -> 0.068405345 | P13: =P11/(P8+P9/2) -> -0.0011128872
A14: MSFT | B14: Microsoft | C14: Stock | D14: Mega-cap tech | E14: 21 | F14: 507.29 | G14: 4871.69 | H14: 10653.09 | I14: 5781.4 | J14: =IF(G14=0,0,I14/G14) -> 1.186734 | K14: 76.44 | L14: =H14/$O$12 -> 0.098770602 | N14: Realized gain/(loss) | O14: 825.08 | P14: -1835.97
A15: PLTR | B15: Palantir Technologies | C15: Stock | D15: Software / AI | E15: 65 | F15: 186.38 | G15: 3722.23 | H15: 12114.7 | I15: 8392.47 | J15: =IF(G15=0,0,I15/G15) -> 2.2546887 | K15: 0 | L15: =H15/$O$12 -> 0.11232199 | N15: of which short-term (YTD) | P15: -7252.17
A16: PRME | B16: Prime Medicine | C16: Stock | D16: Healthcare | E16: 50 | F16: 3.59 | G16: 314 | H16: 179.5 | I16: -134.5 | J16: =IF(G16=0,0,I16/G16) -> -0.42834395 | K16: 0 | L16: =H16/$O$12 -> 0.0016642423 | N16: of which long-term (YTD) | P16: 5416.2
A17: HOOD | B17: Robinhood Markets | C17: Stock | D17: Crypto / fintech | E17: 25 | F17: 104.81 | G17: 1484.76 | H17: 2620.25 | I17: 1135.49 | J17: =IF(G17=0,0,I17/G17) -> 0.76476333 | K17: 0 | L17: =H17/$O$12 -> 0.024293766 | N17: Securities purchased | O17: -3500.24 | P17: -16575.66
A18: SPCX | B18: Space Exploration Techn Cl A | C18: Stock | D18: Drones / space | E18: 10 | F18: 143.69 | G18: 1400 | H18: 1436.9 | I18: 36.9 | J18: =IF(G18=0,0,I18/G18) -> 0.026357143 | K18: 0 | L18: =H18/$O$12 -> 0.013322283 | N18: Securities sold | O18: 21708.09 | P18: 25256.89
A19: SYM | B19: Symbotic | C19: Stock | D19: Software / AI | E19: 50 | F19: 39.67 | G19: 1469.03 | H19: 1983.5 | I19: 514.47 | J19: =IF(G19=0,0,I19/G19) -> 0.35021068 | K19: 0 | L19: =H19/$O$12 -> 0.018390109 | N19: Closing cash (bank deposit program) | O19: 22081.2 | P19: 22081.2
A20: TMC | B20: TMC The Metals Company | C20: Stock | D20: Metals / mining | E20: 100 | F20: 4.77 | G20: 1071 | H20: 477 | I20: -594 | J20: =IF(G20=0,0,I20/G20) -> -0.55462185 | K20: 0 | L20: =H20/$O$12 -> 0.0044225269
A21: URG | B21: Ur-Energy | C21: Stock | D21: Nuclear / uranium | E21: 700 | F21: 1.429 | G21: 1342.43 | H21: 1000.31 | I21: -342.13 | J21: =IF(G21=0,0,I21/G21) -> -0.25485873 | K21: 0 | L21: =H21/$O$12 -> 0.0092744191
A22: WYFI | B22: WhiteFiber | C22: Stock | D22: AI infrastructure | E22: 10 | F22: 18.92 | G22: 321.5 | H22: 189.2 | I22: -132.3 | J22: =IF(G22=0,0,I22/G22) -> -0.41150855 | K22: 0 | L22: =H22/$O$12 -> 0.0017541763
A23: IWMI | B23: NEOS Russell 2000 High Income ETF | C23: ETF | D23: Option-income ETF | E23: 50 | F23: 51.865 | G23: 2046.97 | H23: 2593.25 | I23: 546.28 | J23: =IF(G23=0,0,I23/G23) -> 0.2668725 | K23: 361.85 | L23: =H23/$O$12 -> 0.024043434
A24: SPYI | B24: NEOS S&P 500 High Income ETF | C24: ETF | D24: Option-income ETF | E24: 25 | F24: 53.65 | G24: 1072.3 | H24: 1341.25 | I24: 268.95 | J24: =IF(G24=0,0,I24/G24) -> 0.250816 | K24: 158.35 | L24: =H24/$O$12 -> 0.01243546
A25: SCHD | B25: Schwab US Dividend Equity ETF | C25: ETF | D25: Index ETF | E25: 100 | F25: 34.89 | G25: 2795.99 | H25: 3489 | I25: 693.01 | J25: =IF(G25=0,0,I25/G25) -> 0.24785854 | K25: 104.8 | L25: =H25/$O$12 -> 0.03234842
A26: SPYG | B26: SPDR Portfolio S&P 500 Growth ETF | C26: ETF | D26: Index ETF | E26: 50 | F26: 120.89 | G26: 5227.68 | H26: 6044.5 | I26: 816.82 | J26: =IF(G26=0,0,I26/G26) -> 0.15624904 | K26: 28.85 | L26: =H26/$O$12 -> 0.056041853
A27: VOO | B27: Vanguard S&P 500 ETF | C27: ETF | D27: Index ETF | E27: 4 | F27: 704.89 | G27: 2077.76 | H27: 2819.56 | I27: 741.8 | J27: =IF(G27=0,0,I27/G27) -> 0.3570191 | K27: 29.38 | L27: =H27/$O$12 -> 0.026141677
B29: Total securities (statement $85,775.69 / cost $49,295.15 / unrealized $36,480.53) | G29: =SUM(G8:G27) -> 49295.15 | H29: =SUM(H8:H27) -> 85775.69 | I29: =SUM(I8:I27) -> 36480.53 | J29: =I29/G29 -> 0.74004299 | K29: =SUM(K8:K27) -> 1103.87 | L29: =SUM(L8:L27) -> 0.79527316
B30: Top-10 share of securities | I30: =SUMPRODUCT(LARGE(H8:H27,{1,2,3,4,5,6,7,8,9,10}))/H29 -> 0.87018361
B31: Effective number of holdings (1/HHI) | I31: =1/SUMPRODUCT((H8:H27/H29)^2) -> 9.3960723
A34: August 2026 activity
A35: Date | B35: Type | C35: Description | D35: Symbol | E35: Quantity | F35: Price | G35: Amount
A36: 8/3 | B36: Deposit | C36: ACH deposit | G36: 100
A37: 8/4 | B37: Deposit | C37: ACH deposit | G37: 1000
A38: 8/5 | B38: Dividend | C38: Lowe's | D38: LOW | G38: 8.75
A39: 8/7 | B39: Dividend | C39: YieldMax NVDA Option Income ETF | D39: NVDY | G39: 44.44
A40: 8/13 | B40: Dividend | C40: Apple | D40: AAPL | G40: 8.1
A41: 8/14 | B41: Dividend | C41: YieldMax NVDA Option Income ETF | D41: NVDY | G41: 45.45
A42: 8/17 | B42: Sold | C42: Tesla Inc | D42: TSLA | E42: 40 | F42: 340.74 | G42: 13629.3
A43: 8/17 | B43: Sold | C43: YieldMax NVDA Option Income ETF | D43: NVDY | E43: 460 | F43: 13.15 | G43: 6048.78
A44: 8/17 | B44: Sold | C44: Lowe's | D44: LOW | E44: 7 | F44: 215.7 | G44: 1509.86
A45: 8/17 | B45: Sold | C45: Defiance Daily Target 2X Long OKLO | D45: OKLL | E45: 170 | F45: 3.06 | G45: 520.15
A46: 8/17 | B46: Bought | C46: Space Exploration Techn Cl A | D46: SPCX | E46: 10 | F46: 140 | G46: -1400
A47: 8/17 | B47: Bought | C47: Amazon.com | D47: AMZN | E47: 4 | F47: 265.16 | G47: -1060.64
...

Sheet Cash & banking
A1: Cash, savings and CD — all accounts
A2: Yellow = assumption. Recommendation logic: keep a reserve in checking, apply the rest to the Robinhood margin loan, then hold surplus in a money fund / T-bills at Schwab.
A4: Account | B4: Title | C4: Institution | D4: Balance | E4: As of | F4: Rate | G4: Notes
A5: Trust checking ×4554 | B5: Vanessa Pepino Adraneda Living Trust (dtd 4/11/24) | C5: Centier Bank | D5: 164712.49 | E5: 21 Aug 2026 | F5: 0 | G5: 35-day statement 7/18–8/21: deposits $32,208.62 (payroll from Devoted Health, Archos Medical, Cardinal Home Health, Fergus Medical), debits $21,173.97; no interest paid
A6: 3-month CD ×5501 | B6: Trust | C6: Centier Bank | D6: 51850.33 | E6: 10 Sep 2026 | F6: 0.0334 | G6: Matures 12/10/2026; interest $151.26 paid 9/10; next 10/10
A7: Personal savings ×0081 | B7: Vanessa Adraneda | C7: Robinhood (Coastal Community Bank) | D7: 35321.05 | E7: 31 Aug 2026 | F7: 0.0356 | G7: Interest $104.68 Aug; $321.05 YTD
A8: Child savings ×3365 | B8: Luke Adraneda (with Vanessa) | C8: Robinhood (Coastal Community Bank) | D8: 20065.22 | E8: 31 Aug 2026 | F8: 0.0356 | G8: Interest $59.47 Aug; $65.22 YTD
A9: SEP IRA cash (bank deposit program) | B9: SEP IRA | C9: E*TRADE | D9: 16443.72 | E9: 31 Aug 2026 | F9: 0.0001 | G9: APY 0.010%
A10: UTMA cash (bank deposit program) | B10: Luke UTMA | C10: E*TRADE | D10: 22081.2 | E10: 31 Aug 2026 | F10: 0.0001 | G10: no yield shown
A11: Total cash | D11: =SUM(D5:D10) -> 310474.01 | F11: =SUMPRODUCT(D5:D10,F5:F10)/D11 -> 0.011941111 | G11: blended rate
A12: Annual interest at current rates | D12: =SUMPRODUCT(D5:D10,F5:F10) -> 3707.4047
A14: Assumptions
A15: Money-market yield (SWVXX 7-day, 14 Sep 2026) | D15: 0.0352
A16: Robinhood margin rate | D16: 0.045
A17: Months of outflows to hold as reserve | D17: 3
A18: Checking outflows in statement (35 days) | D18: 21173.97
A19: Payroll deposits in statement (35 days) | D19: 32208.6
A20: Statement days | D20: 35
A22: Derived
A23: Monthly outflows | D23: =D18/D20*30 -> 18149.117
A24: Monthly net payroll | D24: =D19/D20*30 -> 27607.371
A25: Operating reserve to keep in checking | D25: =D23*D17 -> 54447.351
A26: Checking excess available | D26: =D5-D25 -> 110265.14
A27: Cash earning ~0% (checking + E*TRADE sweeps) | D27: =D5+D9+D10 -> 203237.41
A28: Interest foregone per year at money-market yield | D28: =D27*D15 -> 7153.9568
A29: Robinhood margin loan (Robinhood!O14) | D29: =-Robinhood!O14 -> 216910.5
A30: Pay now: checking excess + personal savings | D30: =D26+D7 -> 145586.19
A31: Pay at CD maturity (10 Dec 2026) | D31: =D6 -> 51850.33
A32: Loan remaining after cash | D32: =D29-D30-D31 -> 19473.981
A33: Annual interest saved by paying the loan with cash | D33: =(D30+D31)*D16 -> 8884.6433
A34: Call trigger after paying now (30% maintenance) | D34: =1-(D29-D30)/(Robinhood!O12*0.7) -> 0.76708517

Sheet Consolidation
A1: Consolidation into three Schwab accounts
A3: Today | B3: Title | C3: Destination | D3: Balance | E3: How
A4: Robinhood brokerage 140450008 | B4: Vanessa (individual) | C4: A · Schwab trust brokerage | D4: =Robinhood!O10 -> 220553.58 | E4: Clear the margin loan first; ACATS in kind (fractions liquidated); journal into trust account if titles differ; $100 RH fee, ask Schwab to reimburse
A5: Robinhood personal savings ×0081 | B5: Vanessa | C5: A · Schwab trust brokerage | D5: ='Cash & banking'!D7 -> 35321.05 | E5: Apply to margin loan now; residual to SWVXX
A6: Centier 3-month CD ×5501 | B6: Living Trust | C6: A · Schwab trust brokerage | D6: ='Cash & banking'!D6 -> 51850.33 | E6: At maturity 12/10/2026 → margin loan / T-bills; do not roll
A7: Centier checking ×4554 — excess | B7: Living Trust | C7: A · Schwab trust brokerage | D7: ='Cash & banking'!D26 -> 110265.14 | E7: Excess over reserve → margin loan now; later surplus → SWVXX
A8: Centier checking ×4554 — reserve | B8: Living Trust | C8: Stays at Centier | D8: ='Cash & banking'!D25 -> 54447.351 | E8: Operating account for payroll and bills
A9: E*TRADE SEP IRA 459-855137-203 | B9: Vanessa | C9: B · Schwab SEP IRA | D9: ='SEP IRA'!B53 -> 254650.28 | E9: Like-to-like ACATS in kind; no tax; sweep cash → money fund; no E*TRADE fee
A10: E*TRADE UTMA 459-403795-201 | B10: Vanessa C/F Luke, UTMA/IN | C10: C · Schwab custodial UTMA/IN | D10: ='Luke UTMA'!P12 -> 107856.89 | E10: ACATS in kind; cash → money fund; drop option-income ETFs (kiddie tax)
A11: Robinhood child savings ×3365 | B11: Luke (with Vanessa) | C11: C · Schwab custodial UTMA/IN (or Indiana529) | D11: ='Cash & banking'!D8 -> 20065.22 | E11: Luke's money stays Luke's; Indiana529 earns 20% state credit up to $1,500/yr
A13: Totals by destination
A14: A · Schwab trust brokerage | D14: =SUMIF(C4:C11,"A · Schwab trust brokerage*",D4:D11) -> 417990.1
A15: B · Schwab SEP IRA | D15: =SUMIF(C4:C11,"B · Schwab SEP IRA*",D4:D11) -> 254650.28
A16: C · Schwab custodial UTMA/IN | D16: =SUMIF(C4:C11,"C · Schwab custodial UTMA/IN*",D4:D11) -> 127922.11
A17: Stays at Centier | D17: =SUMIF(C4:C11,"Stays at Centier*",D4:D11) -> 54447.351
A19: Note: destination A total is before the margin payoff — the loan is settled from the cash lines above it, so the net arriving at Schwab is the Robinhood equity plus whatever cash remains.
