Workbook

Sheet Flows & Returns
A1: Account Value, Cash Flows and Returns — Jan 2025 to Aug 2026
A2: Source: RBC Wealth Management statements dated 12/31/2025 (full-year 2025 columns) and 08/31/2026 (2026 year-to-date columns). Blue = figures taken from the statements; black = formulas.
A4: Account | B4: Period | C4: Months | D4: Beginning value | E4: Deposits (as shown) | F4: Withdrawals (as shown) | G4: of which: advisory fees | H4: of which: internal transfer | I4: of which: external cash in/out | J4: Income (div/int/cap-gain dist.) | K4: Change in asset value | L4: Ending value | M4: Check (should be 0) | N4: Investment gain (income + value change) | O4: Gross return (Mod. Dietz) | P4: Net return after fees | Q4: Annualized gross | R4: Realized G/L (YTD) | S4: Unrealized G/L (period end) | T4: Est. annual income
A5: IRA (319-17330) | B5: 2025 | C5: 12 | D5: 162707.7 | E5: 0 | F5: -1678.68 | G5: 1678.68 | H5: 0 | I5: 0 | J5: 14388.04 | K5: 6854.12 | L5: 182271.18 | M5: =D5+E5+F5+J5+K5-L5 -> 0 | N5: =J5+K5 -> 21242.16 | O5: =IF(D5=0,0,N5/(D5+0.5*(E5+F5))) -> 0.13123108 | P5: =IF(D5=0,0,(N5-G5)/(D5+0.5*(E5+F5+G5))) -> 0.12023696 | Q5: =(1+O5)^(12/C5)-1 -> 0.13123108 | R5: 2984.89 | S5: 19543.23 | T5: 4239.7
A6: IRA (319-17330) | B6: 2026 YTD | C6: 8 | D6: 182271.18 | E6: 0 | F6: -1423.04 | G6: 1423.04 | H6: 0 | I6: 0 | J6: 4045.63 | K6: 24865.24 | L6: 209759.01 | M6: =D6+E6+F6+J6+K6-L6 -> 0 | N6: =J6+K6 -> 28910.87 | O6: =IF(D6=0,0,N6/(D6+0.5*(E6+F6))) -> 0.1592362 | P6: =IF(D6=0,0,(N6-G6)/(D6+0.5*(E6+F6+G6))) -> 0.15080733 | Q6: =(1+O6)^(12/C6)-1 -> 0.24812448 | R6: 13970.61 | S6: 30438.4 | T6: 4117.17
A7: Taxable Advisory (319-17342) | B7: 2025 | C7: 12 | D7: 537560.75 | E7: 8600 | F7: -5522.6 | G7: 5521.38 | H7: 8600 | I7: 0 | J7: 31305.19 | K7: 27144.25 | L7: 599087.59 | M7: =D7+E7+F7+J7+K7-L7 -> 0 | N7: =J7+K7 -> 58449.44 | O7: =IF(D7=0,0,N7/(D7+0.5*(E7+F7))) -> 0.10842051 | P7: =IF(D7=0,0,(N7-G7)/(D7+0.5*(E7+F7+G7))) -> 0.097678453 | Q7: =(1+O7)^(12/C7)-1 -> 0.10842051 | R7: -383.49 | S7: 162928.33 | T7: 7053.1
A8: Taxable Advisory (319-17342) | B8: 2026 YTD | C8: 8 | D8: 599087.59 | E8: 38100 | F8: -4622.42 | G8: 4622.42 | H8: 38100 | I8: 0 | J8: 8030.43 | K8: 51293.52 | L8: 691889.12 | M8: =D8+E8+F8+J8+K8-L8 -> 0 | N8: =J8+K8 -> 59323.95 | O8: =IF(D8=0,0,N8/(D8+0.5*(E8+F8))) -> 0.096332265 | P8: =IF(D8=0,0,(N8-G8)/(D8+0.5*(E8+F8+G8))) -> 0.0884941 | Q8: =(1+O8)^(12/C8)-1 -> 0.14792442 | R8: -6575.7 | S8: 220856.64 | T8: 7288.23
A9: Structured Notes (319-17343) | B9: 2025 | C9: 12 | D9: 88754.51 | E9: 12000 | F9: -8600 | G9: 0 | H9: -8600 | I9: 12000 | J9: 12.86 | K9: 5636.85 | L9: 97804.22 | M9: =D9+E9+F9+J9+K9-L9 -> 0 | N9: =J9+K9 -> 5649.71 | O9: =IF(D9=0,0,N9/(D9+0.5*(E9+F9))) -> 0.06245913 | P9: =IF(D9=0,0,(N9-G9)/(D9+0.5*(E9+F9+G9))) -> 0.06245913 | Q9: =(1+O9)^(12/C9)-1 -> 0.06245913 | R9: -3243.65 | S9: 4438.45 | T9: 0
A10: Structured Notes (319-17343) | B10: 2026 YTD | C10: 8 | D10: 97804.22 | E10: 8000 | F10: -38100 | G10: 0 | H10: -38100 | I10: 8000 | J10: 1.45 | K10: 1607.4 | L10: 69313.07 | M10: =D10+E10+F10+J10+K10-L10 -> 0 | N10: =J10+K10 -> 1608.85 | O10: =IF(D10=0,0,N10/(D10+0.5*(E10+F10))) -> 0.019441305 | P10: =IF(D10=0,0,(N10-G10)/(D10+0.5*(E10+F10+G10))) -> 0.019441305 | Q10: =(1+O10)^(12/C10)-1 -> 0.029303238 | R10: 5600 | S10: -324.03 | T10: 0
A11: Joint w/ Mom (319-17346) | B11: 2025 | C11: 12 | D11: 306430.23 | E11: 0 | F11: -3948.23 | G11: 3946.8 | H11: 0 | I11: 0 | J11: 13109.45 | K11: 15008.02 | L11: 330599.47 | M11: =D11+E11+F11+J11+K11-L11 -> 0 | N11: =J11+K11 -> 28117.47 | O11: =IF(D11=0,0,N11/(D11+0.5*(E11+F11))) -> 0.092353113 | P11: =IF(D11=0,0,(N11-G11)/(D11+0.5*(E11+F11+G11))) -> 0.0788784 | Q11: =(1+O11)^(12/C11)-1 -> 0.092353113 | R11: 418.89 | S11: 72121.53 | T11: 15649.26
A12: Joint w/ Mom (319-17346) | B12: 2026 YTD | C12: 8 | D12: 330599.47 | E12: 0 | F12: -32989.42 | G12: 2989.42 | H12: 0 | I12: -30000 | J12: 8819.95 | K12: 18894.83 | L12: 325324.83 | M12: =D12+E12+F12+J12+K12-L12 -> 0 | N12: =J12+K12 -> 27714.78 | O12: =IF(D12=0,0,N12/(D12+0.5*(E12+F12))) -> 0.088234193 | P12: =IF(D12=0,0,(N12-G12)/(D12+0.5*(E12+F12+G12))) -> 0.078344111 | Q12: =(1+O12)^(12/C12)-1 -> 0.13522919 | R12: -1343.71 | S12: 92819.61 | T12: 12079.58
A13: ALL ACCOUNTS | B13: 2025 | C13: 12 | D13: =SUMIF($B$5:$B$12,"2025",D5:D12) -> 1095453.2 | E13: =SUMIF($B$5:$B$12,"2025",E5:E12) -> 20600 | F13: =SUMIF($B$5:$B$12,"2025",F5:F12) -> -19749.51 | G13: =SUMIF($B$5:$B$12,"2025",G5:G12) -> 11146.86 | H13: =SUMIF($B$5:$B$12,"2025",H5:H12) -> 0 | I13: =SUMIF($B$5:$B$12,"2025",I5:I12) -> 12000 | J13: =SUMIF($B$5:$B$12,"2025",J5:J12) -> 58815.54 | K13: =SUMIF($B$5:$B$12,"2025",K5:K12) -> 54643.24 | L13: =SUMIF($B$5:$B$12,"2025",L5:L12) -> 1209762.5 | M13: =D13+E13+F13+J13+K13-L13 -> 0 | N13: =J13+K13 -> 113458.78 | O13: =N13/(D13+0.5*(I13-G13)) -> 0.10353214 | P13: =(N13-G13)/(D13+0.5*I13) -> 0.092888124 | Q13: =(1+O13)^(12/C13)-1 -> 0.10353214 | R13: =SUMIF($B$5:$B$12,"2025",R5:R12) -> -223.36 | S13: =SUMIF($B$5:$B$12,"2025",S5:S12) -> 259031.54 | T13: =SUMIF($B$5:$B$12,"2025",T5:T12) -> 26942.06
A14: ALL ACCOUNTS | B14: 2026 YTD | C14: 8 | D14: =SUMIF($B$5:$B$12,"2026 YTD",D5:D12) -> 1209762.5 | E14: =SUMIF($B$5:$B$12,"2026 YTD",E5:E12) -> 46100 | F14: =SUMIF($B$5:$B$12,"2026 YTD",F5:F12) -> -77134.88 | G14: =SUMIF($B$5:$B$12,"2026 YTD",G5:G12) -> 9034.88 | H14: =SUMIF($B$5:$B$12,"2026 YTD",H5:H12) -> 0 | I14: =SUMIF($B$5:$B$12,"2026 YTD",I5:I12) -> -22000 | J14: =SUMIF($B$5:$B$12,"2026 YTD",J5:J12) -> 20897.46 | K14: =SUMIF($B$5:$B$12,"2026 YTD",K5:K12) -> 96660.99 | L14: =SUMIF($B$5:$B$12,"2026 YTD",L5:L12) -> 1296286 | M14: =D14+E14+F14+J14+K14-L14 -> 0 | N14: =J14+K14 -> 117558.45 | O14: =N14/(D14+0.5*(I14-G14)) -> 0.098437463 | P14: =(N14-G14)/(D14+0.5*I14) -> 0.09052967 | Q14: =(1+O14)^(12/C14)-1 -> 0.1512324 | R14: =SUMIF($B$5:$B$12,"2026 YTD",R5:R12) -> 11651.2 | S14: =SUMIF($B$5:$B$12,"2026 YTD",S5:S12) -> 343790.62 | T14: =SUMIF($B$5:$B$12,"2026 YTD",T5:T12) -> 23484.98
A15: ALL ACCOUNTS — full span 1/1/2025 → 8/31/2026 | B15: 20 mo | C15: 20 | D15: =D13 -> 1095453.2 | E15: =E13+E14 -> 66700 | F15: =F13+F14 -> -96884.39 | G15: =G13+G14 -> 20181.74 | H15: =H13+H14 -> 0 | I15: =I13+I14 -> -10000 | J15: =J13+J14 -> 79713 | K15: =K13+K14 -> 151304.23 | L15: =L14 -> 1296286 | M15: =D15+E15+F15+J15+K15-L15 -> 0 | N15: =J15+K15 -> 231017.23 | O15: =N15/(D15+0.5*(I15-G15)) -> 0.21383311 | P15: =(N15-G15)/(D15+0.5*I15) -> 0.19334667 | Q15: =(1+O15)^(12/C15)-1 -> 0.12329904 | R15: =R13+R14 -> 11427.84 | S15: =S14 -> 343790.62 | T15: =T14 -> 23484.98
A17: Notes and assumptions
A18: • Combined-row returns use external flows only (deposits/withdrawals to/from outside RBC, and fees); the internal transfers between the Structured Notes and Taxable accounts ($8,600 in 2025, $38,100 in 2026) net to zero at the household level.
A19: • 'Withdrawals' on the IRA and Joint statements are quarterly advisory fees: 2025 fees per the statements' Advisory Fee Summary match the withdrawals ($1,678.68 IRA exactly; Taxable $5,521.38 vs $5,522.60; Joint $3,946.80 vs $3,948.23). 2026 fees are inferred from YTD withdrawals (three quarterly bills: Jan/Apr/Jul); Joint 2026 withdrawals also include a $30,000 cash withdrawal funded by the 5/26/2026 sales of JNBSX ($20,000) and LLDYX ($10,000).
A20: • Structured Notes account: deposits are $1,000/month AutoPay from JPMorgan Chase (12 in 2025, 8 in 2026). The $28,000 BMO buffer note matured 7/31/2026 for a $5,600 realized gain; $38,100 was then moved to the Taxable account and a new $36,000 Citibank SPX-linked CD (due 8/29/2031) was bought 8/6/2026.
A21: • Returns are Modified-Dietz approximations (flows assumed mid-period), gross of fees unless labelled 'net'. 'Income' includes reinvested dividends, interest and mutual-fund capital-gain distributions as reported by RBC; 'Change in asset value' is market movement of priced securities.
A22: • Annualized figures for the 8-month 2026 YTD period extrapolate a partial year and should be read with care.

Sheet Holdings by Account
A1: Positions by account — 12/31/2025 vs 8/31/2026
A2: Blue = statement figures. Price return = 8/31/2026 price ÷ 12/31/2025 price − 1 (excludes distributions; mutual-fund and bond-fund total returns are higher than price return). Unrealized % = unrealized gain ÷ RBC net cost (cost includes reinvested distributions).
A4: Account | B4: Symbol / CUSIP | C4: Description | D4: RBC category | E4: Classification | F4: Asset class | G4: Vehicle | H4: Status | I4: Qty 12/31/25 | J4: Price 12/31/25 | K4: Value 12/31/25 | L4: Net cost 12/31/25 | M4: Unrealized 12/31/25 | N4: Qty 8/31/26 | O4: Price 8/31/26 | P4: Value 8/31/26 | Q4: Net cost 8/31/26 | R4: Unrealized 8/31/26 | S4: Unrealized % | T4: Price return Dec→Aug | U4: Weight of total 8/31/26 | V4: Est. annual income | W4: Yield on value
A5: IRA | B5: RDVY | C5: FIRST TRUST RISING DIVIDEND | D5: US Large Cap Equity | E5: US Dividend-growth ETF | F5: Equity | G5: Fund/ETF | H5: New in 2026 | K5: 0 | L5: 0 | M5: 0 | N5: 951.73 | O5: 81.45 | P5: 77518.38 | Q5: 70981.44 | R5: 6536.94 | S5: =IF(Q5=0,"",R5/Q5) -> 0.092093652 | T5: =IF(OR(J5=0,O5=0,J5="",O5="",B5="CASH"),"",O5/J5-1) | U5: =P5/$P$86 -> 0.059800367 | V5: 644.32 | W5: =IF(P5=0,"",V5/P5) -> 0.0083118352
A6: IRA | B6: FFOMX | C6: FIDELITY SELECT PORTFOLIOS | D6: US Large Cap Equity | E6: Sector fund – Technology | F6: Equity | G6: Fund/ETF | H6: Held | I6: 1084.702 | J6: 41.43 | K6: 44939.2 | L6: 34511.62 | M6: 10427.58 | N6: 1121.629 | O6: 54.76 | P6: 61420.4 | Q6: 36037.8 | R6: 25382.6 | S6: =IF(Q6=0,"",R6/Q6) -> 0.70433267 | T6: =IF(OR(J6=0,O6=0,J6="",O6="",B6="CASH"),"",O6/J6-1) -> 0.32174753 | U6: =P6/$P$86 -> 0.047381827 | V6: 0 | W6: =IF(P6=0,"",V6/P6) -> 0
A7: IRA | B7: LLDYX | C7: LORD ABBETT SHORT DURATION | D7: US Corporate Investment Grade Fixed Income | E7: Short-duration IG bond fund | F7: Fixed Income | G7: Fund/ETF | H7: Held | I7: 7009.686 | J7: 3.89 | K7: 27267.68 | L7: 29245.16 | M7: -1977.48 | N7: 6982.959 | O7: 3.82 | P7: 26674.9 | Q7: 29035.5 | R7: -2360.6 | S7: =IF(Q7=0,"",R7/Q7) -> -0.081300477 | T7: =IF(OR(J7=0,O7=0,J7="",O7="",B7="CASH"),"",O7/J7-1) -> -0.017994859 | U7: =P7/$P$86 -> 0.020577943 | V7: 1361.68 | W7: =IF(P7=0,"",V7/P7) -> 0.051047239
A8: IRA | B8: LSYIX | C8: LORD ABBETT TR I | D8: US Corporate High Yield Fixed Income | E8: Short-duration HY bond fund | F8: Fixed Income | G8: Fund/ETF | H8: Held | I8: 1901.779 | J8: 9.78 | K8: 18599.4 | L8: 18223.67 | M8: 375.73 | N8: 2005.762 | O8: 9.61 | P8: 19275.37 | Q8: 19230.48 | R8: 44.89 | S8: =IF(Q8=0,"",R8/Q8) -> 0.0023343151 | T8: =IF(OR(J8=0,O8=0,J8="",O8="",B8="CASH"),"",O8/J8-1) -> -0.017382413 | U8: =P8/$P$86 -> 0.014869689 | V8: 1556.47 | W8: =IF(P8=0,"",V8/P8) -> 0.080749163
A9: IRA | B9: ALAI | C9: ALGER ETF TRUST (THE) | D9: US Large Cap Equity | E9: Thematic ETF – AI | F9: Equity | G9: Fund/ETF | H9: Held | I9: 296.33 | J9: 36.11 | K9: 10700.49 | L9: 10138.11 | M9: 562.38 | N9: 296.33 | O9: 44.69 | P9: 13243 | Q9: 10137.56 | R9: 3105.44 | S9: =IF(Q9=0,"",R9/Q9) -> 0.30633012 | T9: =IF(OR(J9=0,O9=0,J9="",O9="",B9="CASH"),"",O9/J9-1) -> 0.23760731 | U9: =P9/$P$86 -> 0.010216109 | V9: 0 | W9: =IF(P9=0,"",V9/P9) -> 0
A10: IRA | B10: VFFIX | C10: VICTORY PORTFOLIOS | D10: US Government Fixed Income | E10: Gov't/MBS income fund | F10: Fixed Income | G10: Fund/ETF | H10: Held | I10: 1477.978 | J10: 6.8 | K10: 10050.25 | L10: 12080.91 | M10: -2030.66 | N10: 1523.9 | O10: 6.64 | P10: 10118.7 | Q10: 12389.57 | R10: -2270.87 | S10: =IF(Q10=0,"",R10/Q10) -> -0.18328885 | T10: =IF(OR(J10=0,O10=0,J10="",O10="",B10="CASH"),"",O10/J10-1) -> -0.023529412 | U10: =P10/$P$86 -> 0.0078059161 | V10: 554.7 | W10: =IF(P10=0,"",V10/P10) -> 0.054819295
A11: IRA | B11: CASH | C11: RBC INSURED DEPOSITS | D11: Cash | E11: Cash sweep | F11: Cash | G11: Cash | H11: Held | J11: 1 | K11: 492.35 | L11: 492.35 | M11: 0 | O11: 1 | P11: 1508.26 | Q11: 1508.26 | R11: 0 | S11: =IF(Q11=0,"",R11/Q11) -> 0 | T11: =IF(OR(J11=0,O11=0,J11="",O11="",B11="CASH"),"",O11/J11-1) | U11: =P11/$P$86 -> 0.0011635241 | V11: 0 | W11: =IF(P11=0,"",V11/P11) -> 0
A12: IRA | B12: FRDAX | C12: FRANKLIN RISING DIVS ADVISOR | D12: US Large Cap Equity | E12: US Dividend-growth fund | F12: Equity | G12: Fund/ETF | H12: Sold/matured 2026 | I12: 778.426 | J12: 90.21 | K12: 70221.81 | L12: 58036.13 | M12: 12185.68 | P12: 0 | Q12: 0 | R12: 0 | S12: =IF(Q12=0,"",R12/Q12) | T12: =IF(OR(J12=0,O12=0,J12="",O12="",B12="CASH"),"",O12/J12-1) | U12: =P12/$P$86 -> 0 | V12: 0 | W12: =IF(P12=0,"",V12/P12)
A13: Taxable | B13: LGLIX | C13: LORD ABBETT SECS TR | D13: US Large Cap Equity | E13: US Large Growth fund | F13: Equity | G13: Fund/ETF | H13: Held | I13: 1246.618 | J13: 56.75 | K13: 70745.57 | L13: 41612.91 | M13: 29132.66 | N13: 1413.982 | O13: 59.72 | P13: 84443.01 | Q13: 51612.91 | R13: 32830.1 | S13: =IF(Q13=0,"",R13/Q13) -> 0.6360831 | T13: =IF(OR(J13=0,O13=0,J13="",O13="",B13="CASH"),"",O13/J13-1) -> 0.052334802 | U13: =P13/$P$86 -> 0.065142266 | V13: 0 | W13: =IF(P13=0,"",V13/P13) -> 0
A14: Taxable | B14: FFOMX | C14: FIDELITY SELECT PORTFOLIOS | D14: US Large Cap Equity | E14: Sector fund – Technology | F14: Equity | G14: Fund/ETF | H14: Held | I14: 1433.361 | J14: 41.43 | K14: 59384.15 | L14: 45604.65 | M14: 13779.5 | N14: 1482.157 | O14: 54.76 | P14: 81162.92 | Q14: 47621.39 | R14: 33541.53 | S14: =IF(Q14=0,"",R14/Q14) -> 0.70433748 | T14: =IF(OR(J14=0,O14=0,J14="",O14="",B14="CASH"),"",O14/J14-1) -> 0.32174753 | U14: =P14/$P$86 -> 0.062611891 | V14: 0 | W14: =IF(P14=0,"",V14/P14) -> 0
A15: Taxable | B15: AAPL | C15: APPLE INC | D15: US Large Cap Equity | E15: Individual stock – Technology | F15: Equity | G15: Stock | H15: Held | I15: 163.563 | J15: 271.86 | K15: 44466.13 | L15: 10866.53 | M15: 33599.6 | N15: 164.012 | O15: 316.85 | P15: 51967.23 | Q15: 10997.5 | R15: 40969.73 | S15: =IF(Q15=0,"",R15/Q15) -> 3.7253676 | T15: =IF(OR(J15=0,O15=0,J15="",O15="",B15="CASH"),"",O15/J15-1) -> 0.16548959 | U15: =P15/$P$86 -> 0.040089323 | V15: 177.13 | W15: =IF(P15=0,"",V15/P15) -> 0.0034084942
A16: Taxable | B16: LLDYX | C16: LORD ABBETT SHORT DURATION | D16: US Corporate Investment Grade Fixed Income | E16: Short-duration IG bond fund | F16: Fixed Income | G16: Fund/ETF | H16: Held | I16: 11401.449 | J16: 3.89 | K16: 44351.64 | L16: 43811.67 | M16: 539.97 | N16: 11785.181 | O16: 3.82 | P16: 45019.39 | Q16: 45292.27 | R16: -272.88 | S16: =IF(Q16=0,"",R16/Q16) -> -0.0060248691 | T16: =IF(OR(J16=0,O16=0,J16="",O16="",B16="CASH"),"",O16/J16-1) -> -0.017994859 | U16: =P16/$P$86 -> 0.034729519 | V16: 2298.11 | W16: =IF(P16=0,"",V16/P16) -> 0.051047115
A17: Taxable | B17: RDVY | C17: FIRST TRUST RISING DIVIDEND | D17: US Large Cap Equity | E17: US Dividend-growth ETF | F17: Equity | G17: Fund/ETF | H17: New in 2026 | K17: 0 | L17: 0 | M17: 0 | N17: 482.878 | O17: 81.45 | P17: 39330.38 | Q17: 36018.61 | R17: 3311.77 | S17: =IF(Q17=0,"",R17/Q17) -> 0.09194608 | T17: =IF(OR(J17=0,O17=0,J17="",O17="",B17="CASH"),"",O17/J17-1) | U17: =P17/$P$86 -> 0.030340819 | V17: 326.91 | W17: =IF(P17=0,"",V17/P17) -> 0.0083118953
A18: Taxable | B18: FHCIX | C18: FIDELITY ADVISOR HEALTH CARE | D18: US Mid Cap Equity | E18: Sector fund – Health Care | F18: Equity | G18: Fund/ETF | H18: Held | I18: 502.458 | J18: 64.56 | K18: 32438.69 | L18: 33158.92 | M18: -720.23 | N18: 502.458 | O18: 75.68 | P18: 38026.02 | Q18: 33158.92 | R18: 4867.1 | S18: =IF(Q18=0,"",R18/Q18) -> 0.14678102 | T18: =IF(OR(J18=0,O18=0,J18="",O18="",B18="CASH"),"",O18/J18-1) -> 0.17224287 | U18: =P18/$P$86 -> 0.029334591 | V18: 0 | W18: =IF(P18=0,"",V18/P18) -> 0
A19: Taxable | B19: FPACX | C19: INVESTMENT MANAGRS SR TR III | D19: Mixed Assets | E19: Flexible allocation fund | F19: Mixed | G19: Fund/ETF | H19: Held | I19: 590.416 | J19: 43.1 | K19: 25446.93 | L19: 21296.42 | M19: 4150.51 | N19: 593.121 | O19: 47.07 | P19: 27918.21 | Q19: 21418.22 | R19: 6499.99 | S19: =IF(Q19=0,"",R19/Q19) -> 0.30347947 | T19: =IF(OR(J19=0,O19=0,J19="",O19="",B19="CASH"),"",O19/J19-1) -> 0.092111369 | U19: =P19/$P$86 -> 0.021537075 | V19: 743.77 | W19: =IF(P19=0,"",V19/P19) -> 0.026641035
A20: Taxable | B20: AMZN | C20: AMAZON.COM INC | D20: US Large Cap Equity | E20: Individual stock – Consumer Disc. | F20: Equity | G20: Stock | H20: Held | I20: 85 | J20: 230.82 | K20: 19619.7 | L20: 7806.44 | M20: 11813.26 | N20: 103 | O20: 259.77 | P20: 26756.31 | Q20: 12717.38 | R20: 14038.93 | S20: =IF(Q20=0,"",R20/Q20) -> 1.1039168 | T20: =IF(OR(J20=0,O20=0,J20="",O20="",B20="CASH"),"",O20/J20-1) -> 0.12542241 | U20: =P20/$P$86 -> 0.020640745 | V20: 0 | W20: =IF(P20=0,"",V20/P20) -> 0
A21: Taxable | B21: CMSCX | C21: COLUMBIA FDS SER TR I SMALL CAP GROWTH FD CL INSTL | D21: US Small Cap Equity | E21: US Small Cap fund | F21: Equity | G21: Fund/ETF | H21: New in 2026 | K21: 0 | L21: 0 | M21: 0 | N21: 638.896 | O21: 39.23 | P21: 25063.89 | Q21: 25000 | R21: 63.89 | S21: =IF(Q21=0,"",R21/Q21) -> 0.0025556 | T21: =IF(OR(J21=0,O21=0,J21="",O21="",B21="CASH"),"",O21/J21-1) | U21: =P21/$P$86 -> 0.019335154 | V21: 0 | W21: =IF(P21=0,"",V21/P21) -> 0
A22: Taxable | B22: META | C22: META PLATFORMS INC | D22: US Large Cap Equity | E22: Individual stock – Communication | F22: Equity | G22: Stock | H22: Held | I22: 43.285 | J22: 660.09 | K22: 28571.93 | L22: 10582.3 | M22: 17989.63 | N22: 43.366 | O22: 572.34 | P22: 24819.92 | Q22: 10627.77 | R22: 14192.15 | S22: =IF(Q22=0,"",R22/Q22) -> 1.3353836 | T22: =IF(OR(J22=0,O22=0,J22="",O22="",B22="CASH"),"",O22/J22-1) -> -0.13293642 | U22: =P22/$P$86 -> 0.019146947 | V22: 91.07 | W22: =IF(P22=0,"",V22/P22) -> 0.0036692302
A23: Taxable | B23: MSFT | C23: MICROSOFT CORP | D23: US Large Cap Equity | E23: Individual stock – Technology | F23: Equity | G23: Stock | H23: Held | I23: 47.415 | J23: 483.62 | K23: 22930.65 | L23: 12394.67 | M23: 10535.98 | N23: 47.631 | O23: 507.29 | P23: 24162.68 | Q23: 12481.06 | R23: 11681.62 | S23: =IF(Q23=0,"",R23/Q23) -> 0.93594775 | T23: =IF(OR(J23=0,O23=0,J23="",O23="",B23="CASH"),"",O23/J23-1) -> 0.048943385 | U23: =P23/$P$86 -> 0.018639929 | V23: 173.38 | W23: =IF(P23=0,"",V23/P23) -> 0.0071755285
A24: Taxable | B24: TIHBX | C24: TRANSAMERICA FDS | D24: International Equity | E24: International Equity fund | F24: Equity | G24: Fund/ETF | H24: Held | I24: 906.458 | J24: 14.95 | K24: 13551.55 | L24: 10962.58 | M24: 2588.97 | N24: 1283.816 | O24: 16.79 | P24: 21555.27 | Q24: 16962.58 | R24: 4592.69 | S24: =IF(Q24=0,"",R24/Q24) -> 0.27075421 | T24: =IF(OR(J24=0,O24=0,J24="",O24="",B24="CASH"),"",O24/J24-1) -> 0.12307692 | U24: =P24/$P$86 -> 0.016628483 | V24: 363.32 | W24: =IF(P24=0,"",V24/P24) -> 0.016855275
A25: Taxable | B25: EXPE | C25: EXPEDIA GROUP INC | D25: US Mid Cap Equity | E25: Individual stock – Consumer Disc. | F25: Equity | G25: Stock | H25: Held | I25: 60.487 | J25: 283.31 | K25: 17136.69 | L25: 5104.58 | M25: 12032.11 | N25: 60.73 | O25: 317.12 | P25: 19258.67 | Q25: 5162.7 | R25: 14095.97 | S25: =IF(Q25=0,"",R25/Q25) -> 2.7303485 | T25: =IF(OR(J25=0,O25=0,J25="",O25="",B25="CASH"),"",O25/J25-1) -> 0.11933924 | U25: =P25/$P$86 -> 0.014856806 | V25: 116.6 | W25: =IF(P25=0,"",V25/P25) -> 0.006054416
A26: Taxable | B26: KO | C26: COCA COLA COMPANY | D26: US Large Cap Equity | E26: Individual stock – Consumer Staples | F26: Equity | G26: Stock | H26: Held | I26: 188.448 | J26: 69.91 | K26: 13174.4 | L26: 9920.69 | M26: 3253.71 | N26: 190.99 | O26: 88.67 | P26: 16935.1 | Q26: 10121.14 | R26: 6813.96 | S26: =IF(Q26=0,"",R26/Q26) -> 0.67324037 | T26: =IF(OR(J26=0,O26=0,J26="",O26="",B26="CASH"),"",O26/J26-1) -> 0.26834502 | U26: =P26/$P$86 -> 0.013064323 | V26: 404.9 | W26: =IF(P26=0,"",V26/P26) -> 0.023908923
A27: Taxable | B27: CMGIX | C27: BLACKROCK FUNDS-MID CAP | D27: US Mid Cap Equity | E27: US Mid Growth fund | F27: Equity | G27: Fund/ETF | H27: Held | I27: 393.634 | J27: 36.06 | K27: 14194.44 | L27: 11520.64 | M27: 2673.8 | N27: 455.095 | O27: 32.95 | P27: 14995.38 | Q27: 13594.32 | R27: 1401.06 | S27: =IF(Q27=0,"",R27/Q27) -> 0.10306216 | T27: =IF(OR(J27=0,O27=0,J27="",O27="",B27="CASH"),"",O27/J27-1) -> -0.086245147 | U27: =P27/$P$86 -> 0.011567956 | V27: 0 | W27: =IF(P27=0,"",V27/P27) -> 0
A28: Taxable | B28: LBNYX | C28: LORD ABBETT BOND DEBENTURE | D28: US Small Cap Equity | E28: Multi-sector bond fund | F28: Fixed Income | G28: Fund/ETF | H28: Held | I28: 1787.698 | J28: 7.24 | K28: 12942.93 | L28: 12730.26 | M28: 212.67 | N28: 1864.418 | O28: 7.06 | P28: 13162.79 | Q28: 13280.59 | R28: -117.8 | S28: =IF(Q28=0,"",R28/Q28) -> -0.0088700879 | T28: =IF(OR(J28=0,O28=0,J28="",O28="",B28="CASH"),"",O28/J28-1) -> -0.024861878 | U28: =P28/$P$86 -> 0.010154233 | V28: 837.12 | W28: =IF(P28=0,"",V28/P28) -> 0.063597459
A29: Taxable | B29: JPM | C29: JPMORGAN CHASE & CO | D29: US Large Cap Equity | E29: Individual stock – Financials | F29: Equity | G29: Stock | H29: Held | I29: 32.733 | J29: 322.22 | K29: 10547.36 | L29: 4427.18 | M29: 6120.18 | N29: 33.193 | O29: 356.02 | P29: 11817.3 | Q29: 4575.2 | R29: 7242.1 | S29: =IF(Q29=0,"",R29/Q29) -> 1.5829035 | T29: =IF(OR(J29=0,O29=0,J29="",O29="",B29="CASH"),"",O29/J29-1) -> 0.10489728 | U29: =P29/$P$86 -> 0.0091162751 | V29: 199.16 | W29: =IF(P29=0,"",V29/P29) -> 0.016853258
A30: Taxable | B30: SPOT | C30: SPOTIFY TECHNOLOGY S A SHS SPOTIFY TECH SA ORD REG | D30: International Equity | E30: Individual stock – Communication | F30: Equity | G30: Stock | H30: Held | I30: 20 | J30: 580.71 | K30: 11614.2 | L30: 5169.5 | M30: 6444.7 | N30: 20 | O30: 543.62 | P30: 10872.4 | Q30: 5169.5 | R30: 5702.9 | S30: =IF(Q30=0,"",R30/Q30) -> 1.1031821 | T30: =IF(OR(J30=0,O30=0,J30="",O30="",B30="CASH"),"",O30/J30-1) -> -0.06387009 | U30: =P30/$P$86 -> 0.0083873464 | V30: 0 | W30: =IF(P30=0,"",V30/P30) -> 0
A31: Taxable | B31: ALAI | C31: ALGER ETF TRUST (THE) ALGER AI ENABLERS & ADOPTERS | D31: US Large Cap Equity | E31: Thematic ETF – AI | F31: Equity | G31: Fund/ETF | H31: New in 2026 | K31: 0 | L31: 0 | M31: 0 | N31: 240 | O31: 44.69 | P31: 10725.6 | Q31: 10034.38 | R31: 691.22 | S31: =IF(Q31=0,"",R31/Q31) -> 0.068885173 | T31: =IF(OR(J31=0,O31=0,J31="",O31="",B31="CASH"),"",O31/J31-1) | U31: =P31/$P$86 -> 0.0082740998 | V31: 0 | W31: =IF(P31=0,"",V31/P31) -> 0
A32: Taxable | B32: GOOG | C32: ALPHABET INC | D32: US Large Cap Equity | E32: Individual stock – Communication | F32: Equity | G32: Stock | H32: Held | I32: 30.22 | J32: 313.8 | K32: 9483.07 | L32: 3933.6 | M32: 5549.47 | N32: 30.259 | O32: 335.41 | P32: 10149.17 | Q32: 3946.6 | R32: 6202.57 | S32: =IF(Q32=0,"",R32/Q32) -> 1.5716237 | T32: =IF(OR(J32=0,O32=0,J32="",O32="",B32="CASH"),"",O32/J32-1) -> 0.068865519 | U32: =P32/$P$86 -> 0.0078294217 | V32: 26.63 | W32: =IF(P32=0,"",V32/P32) -> 0.0026238599
A33: Taxable | B33: SHLD | C33: GLOBAL X FUNDS | D33: US Large Cap Equity | E33: Individual stock – Industrials (Defense ETF) | F33: Equity | G33: Stock | H33: New in 2026 | K33: 0 | L33: 0 | M33: 0 | N33: 154.447 | O33: 65.48 | P33: 10113.19 | Q33: 10040.19 | R33: 73 | S33: =IF(Q33=0,"",R33/Q33) -> 0.0072707787 | T33: =IF(OR(J33=0,O33=0,J33="",O33="",B33="CASH"),"",O33/J33-1) | U33: =P33/$P$86 -> 0.0078016655 | V33: 51.43 | W33: =IF(P33=0,"",V33/P33) -> 0.0050854379
A34: Taxable | B34: CRM | C34: SALESFORCE INC | D34: US Large Cap Equity | E34: Individual stock – Technology | F34: Equity | G34: Stock | H34: Held | I34: 32.323 | J34: 264.91 | K34: 8562.55 | L34: 7871.38 | M34: 691.17 | N34: 32.542 | O34: 257.54 | P34: 8380.76 | Q34: 7913.35 | R34: 467.41 | S34: =IF(Q34=0,"",R34/Q34) -> 0.059066009 | T34: =IF(OR(J34=0,O34=0,J34="",O34="",B34="CASH"),"",O34/J34-1) -> -0.027820769 | U34: =P34/$P$86 -> 0.0064652089 | V34: 57.27 | W34: =IF(P34=0,"",V34/P34) -> 0.0068335091
A35: Taxable | B35: NFLX | C35: NETFLIX INC COM | D35: US Large Cap Equity | E35: Individual stock – Communication | F35: Equity | G35: Stock | H35: Held | I35: 100 | J35: 93.76 | K35: 9376 | L35: 3149.7 | M35: 6226.3 | N35: 100 | O35: 81.05 | P35: 8105 | Q35: 3149.7 | R35: 4955.3 | S35: =IF(Q35=0,"",R35/Q35) -> 1.5732609 | T35: =IF(OR(J35=0,O35=0,J35="",O35="",B35="CASH"),"",O35/J35-1) -> -0.13555887 | U35: =P35/$P$86 -> 0.0062524781 | V35: 0 | W35: =IF(P35=0,"",V35/P35) -> 0
A36: Taxable | B36: JNJ | C36: JOHNSON & JOHNSON | D36: US Large Cap Equity | E36: Individual stock – Health Care | F36: Equity | G36: Stock | H36: Held | I36: 28.179 | J36: 206.95 | K36: 5831.73 | L36: 5044.48 | M36: 787.25 | N36: 28.492 | O36: 265.85 | P36: 7574.57 | Q36: 5119.07 | R36: 2455.5 | S36: =IF(Q36=0,"",R36/Q36) -> 0.47967697 | T36: =IF(OR(J36=0,O36=0,J36="",O36="",B36="CASH"),"",O36/J36-1) -> 0.28460981 | U36: =P36/$P$86 -> 0.005843286 | V36: 152.72 | W36: =IF(P36=0,"",V36/P36) -> 0.020162201
A37: Taxable | B37: WMB | C37: WILLIAMS COMPANIES INC | D37: US Mid Cap Equity | E37: Individual stock – Energy | F37: Equity | G37: Stock | H37: Held | I37: 89.433 | J37: 60.11 | K37: 5375.84 | L37: 5079.54 | M37: 296.3 | N37: 90.69 | O37: 75.05 | P37: 6806.25 | Q37: 5157.34 | R37: 1648.91 | S37: =IF(Q37=0,"",R37/Q37) -> 0.31972102 | T37: =IF(OR(J37=0,O37=0,J37="",O37="",B37="CASH"),"",O37/J37-1) -> 0.24854434 | U37: =P37/$P$86 -> 0.0052505773 | V37: 190.45 | W37: =IF(P37=0,"",V37/P37) -> 0.027981635
A38: Taxable | B38: CVX | C38: CHEVRON CORPORATION | D38: US Large Cap Equity | E38: Individual stock – Energy | F38: Equity | G38: Stock | H38: Held | I38: 32.368 | J38: 152.41 | K38: 4933.15 | L38: 4989.12 | M38: -55.97 | N38: 32.981 | O38: 206.14 | P38: 6798.79 | Q38: 5104.89 | R38: 1693.9 | S38: =IF(Q38=0,"",R38/Q38) -> 0.3318191 | T38: =IF(OR(J38=0,O38=0,J38="",O38="",B38="CASH"),"",O38/J38-1) -> 0.35253592 | U38: =P38/$P$86 -> 0.0052448224 | V38: 234.83 | W38: =IF(P38=0,"",V38/P38) -> 0.03453997
A39: Taxable | B39: NOW | C39: SERVICENOW INC COM | D39: US Large Cap Equity | E39: Individual stock – Technology | F39: Equity | G39: Stock | H39: Held | I39: 45 | J39: 153.19 | K39: 6893.55 | L39: 5078.79 | M39: 1814.76 | N39: 45 | O39: 147.99 | P39: 6659.55 | Q39: 5078.79 | R39: 1580.76 | S39: =IF(Q39=0,"",R39/Q39) -> 0.31124736 | T39: =IF(OR(J39=0,O39=0,J39="",O39="",B39="CASH"),"",O39/J39-1) -> -0.033944774 | U39: =P39/$P$86 -> 0.0051374078 | V39: 0 | W39: =IF(P39=0,"",V39/P39) -> 0
A40: Taxable | B40: PEP | C40: PEPSICO INC | D40: US Large Cap Equity | E40: Individual stock – Consumer Staples | F40: Equity | G40: Stock | H40: Held | I40: 40.982 | J40: 143.52 | K40: 5881.79 | L40: 5779.14 | M40: 102.65 | N40: 42.235 | O40: 140.34 | P40: 5927.26 | Q40: 5958.16 | R40: -30.9 | S40: =IF(Q40=0,"",R40/Q40) -> -0.0051861649 | T40: =IF(OR(J40=0,O40=0,J40="",O40="",B40="CASH"),"",O40/J40-1) -> -0.022157191 | U40: =P40/$P$86 -> 0.0045724939 | V40: 250.03 | W40: =IF(P40=0,"",V40/P40) -> 0.042183066
A41: Taxable | B41: MDT | C41: MEDTRONIC PLC | D41: International Equity | E41: Individual stock – Health Care | F41: Equity | G41: Stock | H41: Held | I41: 59.324 | J41: 96.06 | K41: 5698.7 | L41: 5648.4 | M41: 50.3 | N41: 60.772 | O41: 90.65 | P41: 5508.99 | Q41: 5776.09 | R41: -267.1 | S41: =IF(Q41=0,"",R41/Q41) -> -0.046242354 | T41: =IF(OR(J41=0,O41=0,J41="",O41="",B41="CASH"),"",O41/J41-1) -> -0.056318967 | U41: =P41/$P$86 -> 0.0042498259 | V41: 175.02 | W41: =IF(P41=0,"",V41/P41) -> 0.031769889
...

Sheet Consolidated Holdings
A1: Consolidated holdings across all four accounts — 8/31/2026
A2: Formulas roll up the 'Holdings by Account' sheet with SUMIF on symbol.
A4: Symbol / CUSIP | B4: Description | C4: Classification | D4: Asset class | E4: Vehicle | F4: Sector (stocks) | G4: Held in | H4: Value 12/31/25 | I4: Value 8/31/26 | J4: Net cost 8/31/26 | K4: Unrealized G/L | L4: Unrealized % | M4: Price return Dec→Aug | N4: Weight 8/31/26 | O4: Cumulative weight | P4: Est. annual income
A5: FFOMX | B5: FIDELITY SELECT PORTFOLIOS | C5: Sector fund – Technology | D5: Equity | E5: Fund/ETF | G5: IRA, Taxable | H5: =SUMIF('Holdings by Account'!$B$5:$B$84,$A5,'Holdings by Account'!$K$5:$K$84) -> 104323.35 | I5: =SUMIF('Holdings by Account'!$B$5:$B$84,$A5,'Holdings by Account'!$P$5:$P$84) -> 142583.32 | J5: =SUMIF('Holdings by Account'!$B$5:$B$84,$A5,'Holdings by Account'!$Q$5:$Q$84) -> 83659.19 | K5: =SUMIF('Holdings by Account'!$B$5:$B$84,$A5,'Holdings by Account'!$R$5:$R$84) -> 58924.13 | L5: =IF(J5=0,"",K5/J5) -> 0.70433541 | M5: 0.32174753 | N5: =I5/SUM($I$5:$I$65) -> 0.10999372 | O5: =SUM($N$5:N5) -> 0.10999372 | P5: =SUMIF('Holdings by Account'!$B$5:$B$84,$A5,'Holdings by Account'!$V$5:$V$84) -> 0
A6: RDVY | B6: FIRST TRUST RISING DIVIDEND | C6: US Dividend-growth ETF | D6: Equity | E6: Fund/ETF | G6: IRA, Taxable | H6: =SUMIF('Holdings by Account'!$B$5:$B$84,$A6,'Holdings by Account'!$K$5:$K$84) -> 0 | I6: =SUMIF('Holdings by Account'!$B$5:$B$84,$A6,'Holdings by Account'!$P$5:$P$84) -> 116848.76 | J6: =SUMIF('Holdings by Account'!$B$5:$B$84,$A6,'Holdings by Account'!$Q$5:$Q$84) -> 107000.05 | K6: =SUMIF('Holdings by Account'!$B$5:$B$84,$A6,'Holdings by Account'!$R$5:$R$84) -> 9848.71 | L6: =IF(J6=0,"",K6/J6) -> 0.092043976 | N6: =I6/SUM($I$5:$I$65) -> 0.090141186 | O6: =SUM($N$5:N6) -> 0.2001349 | P6: =SUMIF('Holdings by Account'!$B$5:$B$84,$A6,'Holdings by Account'!$V$5:$V$84) -> 971.23
A7: LLDYX | B7: LORD ABBETT SHORT DURATION | C7: Short-duration IG bond fund | D7: Fixed Income | E7: Fund/ETF | G7: IRA, Taxable, Joint | H7: =SUMIF('Holdings by Account'!$B$5:$B$84,$A7,'Holdings by Account'!$K$5:$K$84) -> 109112.55 | I7: =SUMIF('Holdings by Account'!$B$5:$B$84,$A7,'Holdings by Account'!$P$5:$P$84) -> 99714.48 | J7: =SUMIF('Holdings by Account'!$B$5:$B$84,$A7,'Holdings by Account'!$Q$5:$Q$84) -> 104832.75 | K7: =SUMIF('Holdings by Account'!$B$5:$B$84,$A7,'Holdings by Account'!$R$5:$R$84) -> -5118.27 | L7: =IF(J7=0,"",K7/J7) -> -0.048823197 | M7: -0.017994859 | N7: =I7/SUM($I$5:$I$65) -> 0.076923208 | O7: =SUM($N$5:N7) -> 0.27705811 | P7: =SUMIF('Holdings by Account'!$B$5:$B$84,$A7,'Holdings by Account'!$V$5:$V$84) -> 5090.14
A8: LGLIX | B8: LORD ABBETT SECS TR | C8: US Large Growth fund | D8: Equity | E8: Fund/ETF | G8: Taxable | H8: =SUMIF('Holdings by Account'!$B$5:$B$84,$A8,'Holdings by Account'!$K$5:$K$84) -> 70745.57 | I8: =SUMIF('Holdings by Account'!$B$5:$B$84,$A8,'Holdings by Account'!$P$5:$P$84) -> 84443.01 | J8: =SUMIF('Holdings by Account'!$B$5:$B$84,$A8,'Holdings by Account'!$Q$5:$Q$84) -> 51612.91 | K8: =SUMIF('Holdings by Account'!$B$5:$B$84,$A8,'Holdings by Account'!$R$5:$R$84) -> 32830.1 | L8: =IF(J8=0,"",K8/J8) -> 0.6360831 | M8: 0.052334802 | N8: =I8/SUM($I$5:$I$65) -> 0.065142266 | O8: =SUM($N$5:N8) -> 0.34220038 | P8: =SUMIF('Holdings by Account'!$B$5:$B$84,$A8,'Holdings by Account'!$V$5:$V$84) -> 0
A9: AAPL | B9: APPLE INC | C9: Individual stock – Technology | D9: Equity | E9: Stock | F9: Technology | G9: Taxable, Joint | H9: =SUMIF('Holdings by Account'!$B$5:$B$84,$A9,'Holdings by Account'!$K$5:$K$84) -> 69848.18 | I9: =SUMIF('Holdings by Account'!$B$5:$B$84,$A9,'Holdings by Account'!$P$5:$P$84) -> 81631.01 | J9: =SUMIF('Holdings by Account'!$B$5:$B$84,$A9,'Holdings by Account'!$Q$5:$Q$84) -> 15288.87 | K9: =SUMIF('Holdings by Account'!$B$5:$B$84,$A9,'Holdings by Account'!$R$5:$R$84) -> 66342.14 | L9: =IF(J9=0,"",K9/J9) -> 4.3392442 | M9: 0.16548959 | N9: =I9/SUM($I$5:$I$65) -> 0.062972992 | O9: =SUM($N$5:N9) -> 0.40517337 | P9: =SUMIF('Holdings by Account'!$B$5:$B$84,$A9,'Holdings by Account'!$V$5:$V$84) -> 278.24
A10: MSFT | B10: MICROSOFT CORP | C10: Individual stock – Technology | D10: Equity | E10: Stock | F10: Technology | G10: Taxable, Joint | H10: =SUMIF('Holdings by Account'!$B$5:$B$84,$A10,'Holdings by Account'!$K$5:$K$84) -> 46995.87 | I10: =SUMIF('Holdings by Account'!$B$5:$B$84,$A10,'Holdings by Account'!$P$5:$P$84) -> 49520.94 | J10: =SUMIF('Holdings by Account'!$B$5:$B$84,$A10,'Holdings by Account'!$Q$5:$Q$84) -> 17228.64 | K10: =SUMIF('Holdings by Account'!$B$5:$B$84,$A10,'Holdings by Account'!$R$5:$R$84) -> 32292.3 | L10: =IF(J10=0,"",K10/J10) -> 1.8743383 | M10: 0.048943385 | N10: =I10/SUM($I$5:$I$65) -> 0.038202171 | O10: =SUM($N$5:N10) -> 0.44337554 | P10: =SUMIF('Holdings by Account'!$B$5:$B$84,$A10,'Holdings by Account'!$V$5:$V$84) -> 355.34
A11: JNBSX | B11: JPMORGAN TR I | C11: Income builder (multi-asset) | D11: Mixed | E11: Fund/ETF | G11: Joint | H11: =SUMIF('Holdings by Account'!$B$5:$B$84,$A11,'Holdings by Account'!$K$5:$K$84) -> 64123.34 | I11: =SUMIF('Holdings by Account'!$B$5:$B$84,$A11,'Holdings by Account'!$P$5:$P$84) -> 48801.29 | J11: =SUMIF('Holdings by Account'!$B$5:$B$84,$A11,'Holdings by Account'!$Q$5:$Q$84) -> 46670.75 | K11: =SUMIF('Holdings by Account'!$B$5:$B$84,$A11,'Holdings by Account'!$R$5:$R$84) -> 2130.54 | L11: =IF(J11=0,"",K11/J11) -> 0.045650434 | M11: 0.036259542 | N11: =I11/SUM($I$5:$I$65) -> 0.037647008 | O11: =SUM($N$5:N11) -> 0.48102255 | P11: =SUMIF('Holdings by Account'!$B$5:$B$84,$A11,'Holdings by Account'!$V$5:$V$84) -> 2857.98
A12: LSYIX | B12: LORD ABBETT TR I | C12: Short-duration HY bond fund | D12: Fixed Income | E12: Fund/ETF | G12: IRA, Joint | H12: =SUMIF('Holdings by Account'!$B$5:$B$84,$A12,'Holdings by Account'!$K$5:$K$84) -> 42158.56 | I12: =SUMIF('Holdings by Account'!$B$5:$B$84,$A12,'Holdings by Account'!$P$5:$P$84) -> 43690.75 | J12: =SUMIF('Holdings by Account'!$B$5:$B$84,$A12,'Holdings by Account'!$Q$5:$Q$84) -> 43588.97 | K12: =SUMIF('Holdings by Account'!$B$5:$B$84,$A12,'Holdings by Account'!$R$5:$R$84) -> 101.78 | L12: =IF(J12=0,"",K12/J12) -> 0.0023349944 | M12: -0.017382413 | N12: =I12/SUM($I$5:$I$65) -> 0.03370456 | O12: =SUM($N$5:N12) -> 0.51472711 | P12: =SUMIF('Holdings by Account'!$B$5:$B$84,$A12,'Holdings by Account'!$V$5:$V$84) -> 3527.99
A13: FHCIX | B13: FIDELITY ADVISOR HEALTH CARE | C13: Sector fund – Health Care | D13: Equity | E13: Fund/ETF | G13: Taxable | H13: =SUMIF('Holdings by Account'!$B$5:$B$84,$A13,'Holdings by Account'!$K$5:$K$84) -> 32438.69 | I13: =SUMIF('Holdings by Account'!$B$5:$B$84,$A13,'Holdings by Account'!$P$5:$P$84) -> 38026.02 | J13: =SUMIF('Holdings by Account'!$B$5:$B$84,$A13,'Holdings by Account'!$Q$5:$Q$84) -> 33158.92 | K13: =SUMIF('Holdings by Account'!$B$5:$B$84,$A13,'Holdings by Account'!$R$5:$R$84) -> 4867.1 | L13: =IF(J13=0,"",K13/J13) -> 0.14678102 | M13: 0.17224287 | N13: =I13/SUM($I$5:$I$65) -> 0.029334591 | O13: =SUM($N$5:N13) -> 0.5440617 | P13: =SUMIF('Holdings by Account'!$B$5:$B$84,$A13,'Holdings by Account'!$V$5:$V$84) -> 0
A14: CSOIX | B14: CREDIT SUISSE STRATEGIC | C14: Strategic income (HY) fund | D14: Fixed Income | E14: Fund/ETF | G14: Joint | H14: =SUMIF('Holdings by Account'!$B$5:$B$84,$A14,'Holdings by Account'!$K$5:$K$84) -> 37893.91 | I14: =SUMIF('Holdings by Account'!$B$5:$B$84,$A14,'Holdings by Account'!$P$5:$P$84) -> 37219.42 | J14: =SUMIF('Holdings by Account'!$B$5:$B$84,$A14,'Holdings by Account'!$Q$5:$Q$84) -> 40036.57 | K14: =SUMIF('Holdings by Account'!$B$5:$B$84,$A14,'Holdings by Account'!$R$5:$R$84) -> -2817.15 | L14: =IF(J14=0,"",K14/J14) -> -0.070364419 | M14: -0.023454158 | N14: =I14/SUM($I$5:$I$65) -> 0.028712351 | O14: =SUM($N$5:N14) -> 0.57277405 | P14: =SUMIF('Holdings by Account'!$B$5:$B$84,$A14,'Holdings by Account'!$V$5:$V$84) -> 2600.48
A15: 17290GZT7 | B15: CITIBANK N A C/D FDIC INS TO LIMITS | C15: Market-linked CD – SPX | D15: Structured | E15: Structured | G15: Struct. Notes | H15: =SUMIF('Holdings by Account'!$B$5:$B$84,$A15,'Holdings by Account'!$K$5:$K$84) -> 0 | I15: =SUMIF('Holdings by Account'!$B$5:$B$84,$A15,'Holdings by Account'!$P$5:$P$84) -> 35362.8 | J15: =SUMIF('Holdings by Account'!$B$5:$B$84,$A15,'Holdings by Account'!$Q$5:$Q$84) -> 36000 | K15: =SUMIF('Holdings by Account'!$B$5:$B$84,$A15,'Holdings by Account'!$R$5:$R$84) -> -637.2 | L15: =IF(J15=0,"",K15/J15) -> -0.0177 | N15: =I15/SUM($I$5:$I$65) -> 0.02728009 | O15: =SUM($N$5:N15) -> 0.60005414 | P15: =SUMIF('Holdings by Account'!$B$5:$B$84,$A15,'Holdings by Account'!$V$5:$V$84) -> 0
A16: 44330UAS1 | B16: HSBC BANK USA NA C/D FDIC INS TO LIMITS | C16: Market-linked CD – NDX | D16: Structured | E16: Structured | G16: Struct. Notes | H16: =SUMIF('Holdings by Account'!$B$5:$B$84,$A16,'Holdings by Account'!$K$5:$K$84) -> 31434 | I16: =SUMIF('Holdings by Account'!$B$5:$B$84,$A16,'Holdings by Account'!$P$5:$P$84) -> 32301 | J16: =SUMIF('Holdings by Account'!$B$5:$B$84,$A16,'Holdings by Account'!$Q$5:$Q$84) -> 31987.83 | K16: =SUMIF('Holdings by Account'!$B$5:$B$84,$A16,'Holdings by Account'!$R$5:$R$84) -> 313.17 | L16: =IF(J16=0,"",K16/J16) -> 0.0097902859 | M16: 0.0275816 | N16: =I16/SUM($I$5:$I$65) -> 0.024918112 | O16: =SUM($N$5:N16) -> 0.62497225 | P16: =SUMIF('Holdings by Account'!$B$5:$B$84,$A16,'Holdings by Account'!$V$5:$V$84) -> 0
A17: FPACX | B17: INVESTMENT MANAGRS SR TR III | C17: Flexible allocation fund | D17: Mixed | E17: Fund/ETF | G17: Taxable | H17: =SUMIF('Holdings by Account'!$B$5:$B$84,$A17,'Holdings by Account'!$K$5:$K$84) -> 25446.93 | I17: =SUMIF('Holdings by Account'!$B$5:$B$84,$A17,'Holdings by Account'!$P$5:$P$84) -> 27918.21 | J17: =SUMIF('Holdings by Account'!$B$5:$B$84,$A17,'Holdings by Account'!$Q$5:$Q$84) -> 21418.22 | K17: =SUMIF('Holdings by Account'!$B$5:$B$84,$A17,'Holdings by Account'!$R$5:$R$84) -> 6499.99 | L17: =IF(J17=0,"",K17/J17) -> 0.30347947 | M17: 0.092111369 | N17: =I17/SUM($I$5:$I$65) -> 0.021537075 | O17: =SUM($N$5:N17) -> 0.64650933 | P17: =SUMIF('Holdings by Account'!$B$5:$B$84,$A17,'Holdings by Account'!$V$5:$V$84) -> 743.77
A18: AMZN | B18: AMAZON.COM INC | C18: Individual stock – Consumer Disc. | D18: Equity | E18: Stock | F18: Consumer Disc. | G18: Taxable | H18: =SUMIF('Holdings by Account'!$B$5:$B$84,$A18,'Holdings by Account'!$K$5:$K$84) -> 19619.7 | I18: =SUMIF('Holdings by Account'!$B$5:$B$84,$A18,'Holdings by Account'!$P$5:$P$84) -> 26756.31 | J18: =SUMIF('Holdings by Account'!$B$5:$B$84,$A18,'Holdings by Account'!$Q$5:$Q$84) -> 12717.38 | K18: =SUMIF('Holdings by Account'!$B$5:$B$84,$A18,'Holdings by Account'!$R$5:$R$84) -> 14038.93 | L18: =IF(J18=0,"",K18/J18) -> 1.1039168 | M18: 0.12542241 | N18: =I18/SUM($I$5:$I$65) -> 0.020640745 | O18: =SUM($N$5:N18) -> 0.66715007 | P18: =SUMIF('Holdings by Account'!$B$5:$B$84,$A18,'Holdings by Account'!$V$5:$V$84) -> 0
A19: KO | B19: COCA COLA COMPANY | C19: Individual stock – Consumer Staples | D19: Equity | E19: Stock | F19: Consumer Staples | G19: Taxable, Joint | H19: =SUMIF('Holdings by Account'!$B$5:$B$84,$A19,'Holdings by Account'!$K$5:$K$84) -> 20369.23 | I19: =SUMIF('Holdings by Account'!$B$5:$B$84,$A19,'Holdings by Account'!$P$5:$P$84) -> 26183.73 | J19: =SUMIF('Holdings by Account'!$B$5:$B$84,$A19,'Holdings by Account'!$Q$5:$Q$84) -> 15213.62 | K19: =SUMIF('Holdings by Account'!$B$5:$B$84,$A19,'Holdings by Account'!$R$5:$R$84) -> 10970.11 | L19: =IF(J19=0,"",K19/J19) -> 0.72107165 | M19: 0.26834502 | N19: =I19/SUM($I$5:$I$65) -> 0.020199037 | O19: =SUM($N$5:N19) -> 0.68734911 | P19: =SUMIF('Holdings by Account'!$B$5:$B$84,$A19,'Holdings by Account'!$V$5:$V$84) -> 626.02
A20: CMSCX | B20: COLUMBIA FDS SER TR I SMALL CAP GROWTH FD CL INSTL | C20: US Small Cap fund | D20: Equity | E20: Fund/ETF | G20: Taxable | H20: =SUMIF('Holdings by Account'!$B$5:$B$84,$A20,'Holdings by Account'!$K$5:$K$84) -> 0 | I20: =SUMIF('Holdings by Account'!$B$5:$B$84,$A20,'Holdings by Account'!$P$5:$P$84) -> 25063.89 | J20: =SUMIF('Holdings by Account'!$B$5:$B$84,$A20,'Holdings by Account'!$Q$5:$Q$84) -> 25000 | K20: =SUMIF('Holdings by Account'!$B$5:$B$84,$A20,'Holdings by Account'!$R$5:$R$84) -> 63.89 | L20: =IF(J20=0,"",K20/J20) -> 0.0025556 | N20: =I20/SUM($I$5:$I$65) -> 0.019335154 | O20: =SUM($N$5:N20) -> 0.70668426 | P20: =SUMIF('Holdings by Account'!$B$5:$B$84,$A20,'Holdings by Account'!$V$5:$V$84) -> 0
A21: META | B21: META PLATFORMS INC | C21: Individual stock – Communication | D21: Equity | E21: Stock | F21: Communication | G21: Taxable | H21: =SUMIF('Holdings by Account'!$B$5:$B$84,$A21,'Holdings by Account'!$K$5:$K$84) -> 28571.93 | I21: =SUMIF('Holdings by Account'!$B$5:$B$84,$A21,'Holdings by Account'!$P$5:$P$84) -> 24819.92 | J21: =SUMIF('Holdings by Account'!$B$5:$B$84,$A21,'Holdings by Account'!$Q$5:$Q$84) -> 10627.77 | K21: =SUMIF('Holdings by Account'!$B$5:$B$84,$A21,'Holdings by Account'!$R$5:$R$84) -> 14192.15 | L21: =IF(J21=0,"",K21/J21) -> 1.3353836 | M21: -0.13293642 | N21: =I21/SUM($I$5:$I$65) -> 0.019146947 | O21: =SUM($N$5:N21) -> 0.72583121 | P21: =SUMIF('Holdings by Account'!$B$5:$B$84,$A21,'Holdings by Account'!$V$5:$V$84) -> 91.07
A22: ALAI | B22: ALGER ETF TRUST (THE) | C22: Thematic ETF – AI | D22: Equity | E22: Fund/ETF | G22: IRA, Taxable | H22: =SUMIF('Holdings by Account'!$B$5:$B$84,$A22,'Holdings by Account'!$K$5:$K$84) -> 10700.49 | I22: =SUMIF('Holdings by Account'!$B$5:$B$84,$A22,'Holdings by Account'!$P$5:$P$84) -> 23968.6 | J22: =SUMIF('Holdings by Account'!$B$5:$B$84,$A22,'Holdings by Account'!$Q$5:$Q$84) -> 20171.94 | K22: =SUMIF('Holdings by Account'!$B$5:$B$84,$A22,'Holdings by Account'!$R$5:$R$84) -> 3796.66 | L22: =IF(J22=0,"",K22/J22) -> 0.18821492 | M22: 0.23760731 | N22: =I22/SUM($I$5:$I$65) -> 0.018490209 | O22: =SUM($N$5:N22) -> 0.74432142 | P22: =SUMIF('Holdings by Account'!$B$5:$B$84,$A22,'Holdings by Account'!$V$5:$V$84) -> 0
A23: JPM | B23: JPMORGAN CHASE & CO | C23: Individual stock – Financials | D23: Equity | E23: Stock | F23: Financials | G23: Taxable, Joint | H23: =SUMIF('Holdings by Account'!$B$5:$B$84,$A23,'Holdings by Account'!$K$5:$K$84) -> 20703.25 | I23: =SUMIF('Holdings by Account'!$B$5:$B$84,$A23,'Holdings by Account'!$P$5:$P$84) -> 23195.98 | J23: =SUMIF('Holdings by Account'!$B$5:$B$84,$A23,'Holdings by Account'!$Q$5:$Q$84) -> 8104.56 | K23: =SUMIF('Holdings by Account'!$B$5:$B$84,$A23,'Holdings by Account'!$R$5:$R$84) -> 15091.42 | L23: =IF(J23=0,"",K23/J23) -> 1.86209 | M23: 0.10489728 | N23: =I23/SUM($I$5:$I$65) -> 0.017894183 | O23: =SUM($N$5:N23) -> 0.7622156 | P23: =SUMIF('Holdings by Account'!$B$5:$B$84,$A23,'Holdings by Account'!$V$5:$V$84) -> 390.92
A24: TIHBX | B24: TRANSAMERICA FDS | C24: International Equity fund | D24: Equity | E24: Fund/ETF | G24: Taxable | H24: =SUMIF('Holdings by Account'!$B$5:$B$84,$A24,'Holdings by Account'!$K$5:$K$84) -> 13551.55 | I24: =SUMIF('Holdings by Account'!$B$5:$B$84,$A24,'Holdings by Account'!$P$5:$P$84) -> 21555.27 | J24: =SUMIF('Holdings by Account'!$B$5:$B$84,$A24,'Holdings by Account'!$Q$5:$Q$84) -> 16962.58 | K24: =SUMIF('Holdings by Account'!$B$5:$B$84,$A24,'Holdings by Account'!$R$5:$R$84) -> 4592.69 | L24: =IF(J24=0,"",K24/J24) -> 0.27075421 | M24: 0.12307692 | N24: =I24/SUM($I$5:$I$65) -> 0.016628483 | O24: =SUM($N$5:N24) -> 0.77884409 | P24: =SUMIF('Holdings by Account'!$B$5:$B$84,$A24,'Holdings by Account'!$V$5:$V$84) -> 363.32
A25: EXPE | B25: EXPEDIA GROUP INC | C25: Individual stock – Consumer Disc. | D25: Equity | E25: Stock | F25: Consumer Disc. | G25: Taxable | H25: =SUMIF('Holdings by Account'!$B$5:$B$84,$A25,'Holdings by Account'!$K$5:$K$84) -> 17136.69 | I25: =SUMIF('Holdings by Account'!$B$5:$B$84,$A25,'Holdings by Account'!$P$5:$P$84) -> 19258.67 | J25: =SUMIF('Holdings by Account'!$B$5:$B$84,$A25,'Holdings by Account'!$Q$5:$Q$84) -> 5162.7 | K25: =SUMIF('Holdings by Account'!$B$5:$B$84,$A25,'Holdings by Account'!$R$5:$R$84) -> 14095.97 | L25: =IF(J25=0,"",K25/J25) -> 2.7303485 | M25: 0.11933924 | N25: =I25/SUM($I$5:$I$65) -> 0.014856806 | O25: =SUM($N$5:N25) -> 0.79370089 | P25: =SUMIF('Holdings by Account'!$B$5:$B$84,$A25,'Holdings by Account'!$V$5:$V$84) -> 116.6
A26: CMGIX | B26: BLACKROCK FUNDS-MID CAP | C26: US Mid Growth fund | D26: Equity | E26: Fund/ETF | G26: Taxable | H26: =SUMIF('Holdings by Account'!$B$5:$B$84,$A26,'Holdings by Account'!$K$5:$K$84) -> 14194.44 | I26: =SUMIF('Holdings by Account'!$B$5:$B$84,$A26,'Holdings by Account'!$P$5:$P$84) -> 14995.38 | J26: =SUMIF('Holdings by Account'!$B$5:$B$84,$A26,'Holdings by Account'!$Q$5:$Q$84) -> 13594.32 | K26: =SUMIF('Holdings by Account'!$B$5:$B$84,$A26,'Holdings by Account'!$R$5:$R$84) -> 1401.06 | L26: =IF(J26=0,"",K26/J26) -> 0.10306216 | M26: -0.086245147 | N26: =I26/SUM($I$5:$I$65) -> 0.011567956 | O26: =SUM($N$5:N26) -> 0.80526885 | P26: =SUMIF('Holdings by Account'!$B$5:$B$84,$A26,'Holdings by Account'!$V$5:$V$84) -> 0
A27: HD | B27: HOME DEPOT INC | C27: Individual stock – Consumer Disc. | D27: Equity | E27: Stock | F27: Consumer Disc. | G27: Taxable, Joint | H27: =SUMIF('Holdings by Account'!$B$5:$B$84,$A27,'Holdings by Account'!$K$5:$K$84) -> 13775.25 | I27: =SUMIF('Holdings by Account'!$B$5:$B$84,$A27,'Holdings by Account'!$P$5:$P$84) -> 13307.01 | J27: =SUMIF('Holdings by Account'!$B$5:$B$84,$A27,'Holdings by Account'!$Q$5:$Q$84) -> 10287.12 | K27: =SUMIF('Holdings by Account'!$B$5:$B$84,$A27,'Holdings by Account'!$R$5:$R$84) -> 3019.89 | L27: =IF(J27=0,"",K27/J27) -> 0.2935603 | M27: -0.047282767 | N27: =I27/SUM($I$5:$I$65) -> 0.010265489 | O27: =SUM($N$5:N27) -> 0.81553434 | P27: =SUMIF('Holdings by Account'!$B$5:$B$84,$A27,'Holdings by Account'!$V$5:$V$84) -> 378.31
A28: LBNYX | B28: LORD ABBETT BOND DEBENTURE | C28: Multi-sector bond fund | D28: Fixed Income | E28: Fund/ETF | G28: Taxable | H28: =SUMIF('Holdings by Account'!$B$5:$B$84,$A28,'Holdings by Account'!$K$5:$K$84) -> 12942.93 | I28: =SUMIF('Holdings by Account'!$B$5:$B$84,$A28,'Holdings by Account'!$P$5:$P$84) -> 13162.79 | J28: =SUMIF('Holdings by Account'!$B$5:$B$84,$A28,'Holdings by Account'!$Q$5:$Q$84) -> 13280.59 | K28: =SUMIF('Holdings by Account'!$B$5:$B$84,$A28,'Holdings by Account'!$R$5:$R$84) -> -117.8 | L28: =IF(J28=0,"",K28/J28) -> -0.0088700879 | M28: -0.024861878 | N28: =I28/SUM($I$5:$I$65) -> 0.010154233 | O28: =SUM($N$5:N28) -> 0.82568857 | P28: =SUMIF('Holdings by Account'!$B$5:$B$84,$A28,'Holdings by Account'!$V$5:$V$84) -> 837.12
A29: TXN | B29: TEXAS INSTRUMENTS INCORPORATED | C29: Individual stock – Technology | D29: Equity | E29: Stock | F29: Technology | G29: Joint | H29: =SUMIF('Holdings by Account'!$B$5:$B$84,$A29,'Holdings by Account'!$K$5:$K$84) -> 8163.02 | I29: =SUMIF('Holdings by Account'!$B$5:$B$84,$A29,'Holdings by Account'!$P$5:$P$84) -> 12477.21 | J29: =SUMIF('Holdings by Account'!$B$5:$B$84,$A29,'Holdings by Account'!$Q$5:$Q$84) -> 5343.19 | K29: =SUMIF('Holdings by Account'!$B$5:$B$84,$A29,'Holdings by Account'!$R$5:$R$84) -> 7134.02 | L29: =IF(J29=0,"",K29/J29) -> 1.3351612 | M29: 0.50389071 | N29: =I29/SUM($I$5:$I$65) -> 0.0096253525 | O29: =SUM($N$5:N29) -> 0.83531392 | P29: =SUMIF('Holdings by Account'!$B$5:$B$84,$A29,'Holdings by Account'!$V$5:$V$84) -> 271.63
A30: AMGN | B30: AMGEN INC | C30: Individual stock – Health Care | D30: Equity | E30: Stock | F30: Health Care | G30: Joint | H30: =SUMIF('Holdings by Account'!$B$5:$B$84,$A30,'Holdings by Account'!$K$5:$K$84) -> 8711.32 | I30: =SUMIF('Holdings by Account'!$B$5:$B$84,$A30,'Holdings by Account'!$P$5:$P$84) -> 11603.28 | J30: =SUMIF('Holdings by Account'!$B$5:$B$84,$A30,'Holdings by Account'!$Q$5:$Q$84) -> 5191.93 | K30: =SUMIF('Holdings by Account'!$B$5:$B$84,$A30,'Holdings by Account'!$R$5:$R$84) -> 6411.35 | L30: =IF(J30=0,"",K30/J30) -> 1.2348683 | M30: 0.31337264 | N30: =I30/SUM($I$5:$I$65) -> 0.0089511726 | O30: =SUM($N$5:N30) -> 0.8442651 | P30: =SUMIF('Holdings by Account'!$B$5:$B$84,$A30,'Holdings by Account'!$V$5:$V$84) -> 272.08
A31: SPOT | B31: SPOTIFY TECHNOLOGY S A SHS SPOTIFY TECH SA ORD REG | C31: Individual stock – Communication | D31: Equity | E31: Stock | F31: Communication | G31: Taxable | H31: =SUMIF('Holdings by Account'!$B$5:$B$84,$A31,'Holdings by Account'!$K$5:$K$84) -> 11614.2 | I31: =SUMIF('Holdings by Account'!$B$5:$B$84,$A31,'Holdings by Account'!$P$5:$P$84) -> 10872.4 | J31: =SUMIF('Holdings by Account'!$B$5:$B$84,$A31,'Holdings by Account'!$Q$5:$Q$84) -> 5169.5 | K31: =SUMIF('Holdings by Account'!$B$5:$B$84,$A31,'Holdings by Account'!$R$5:$R$84) -> 5702.9 | L31: =IF(J31=0,"",K31/J31) -> 1.1031821 | M31: -0.06387009 | N31: =I31/SUM($I$5:$I$65) -> 0.0083873464 | O31: =SUM($N$5:N31) -> 0.85265244 | P31: =SUMIF('Holdings by Account'!$B$5:$B$84,$A31,'Holdings by Account'!$V$5:$V$84) -> 0
A32: MDT | B32: MEDTRONIC PLC | C32: Individual stock – Health Care | D32: Equity | E32: Stock | F32: Health Care | G32: Taxable, Joint | H32: =SUMIF('Holdings by Account'!$B$5:$B$84,$A32,'Holdings by Account'!$K$5:$K$84) -> 11242.68 | I32: =SUMIF('Holdings by Account'!$B$5:$B$84,$A32,'Holdings by Account'!$P$5:$P$84) -> 10868.39 | J32: =SUMIF('Holdings by Account'!$B$5:$B$84,$A32,'Holdings by Account'!$Q$5:$Q$84) -> 10606.65 | K32: =SUMIF('Holdings by Account'!$B$5:$B$84,$A32,'Holdings by Account'!$R$5:$R$84) -> 261.74 | L32: =IF(J32=0,"",K32/J32) -> 0.024676972 | M32: -0.056318967 | N32: =I32/SUM($I$5:$I$65) -> 0.008384253 | O32: =SUM($N$5:N32) -> 0.8610367 | P32: =SUMIF('Holdings by Account'!$B$5:$B$84,$A32,'Holdings by Account'!$V$5:$V$84) -> 345.29
A33: XOM | B33: EXXONMOBIL HOLDINGS | C33: Individual stock – Energy | D33: Equity | E33: Stock | F33: Energy | G33: Joint | H33: =SUMIF('Holdings by Account'!$B$5:$B$84,$A33,'Holdings by Account'!$K$5:$K$84) -> 7716.27 | I33: =SUMIF('Holdings by Account'!$B$5:$B$84,$A33,'Holdings by Account'!$P$5:$P$84) -> 10462.38 | J33: =SUMIF('Holdings by Account'!$B$5:$B$84,$A33,'Holdings by Account'!$Q$5:$Q$84) -> 5349.76 | K33: =SUMIF('Holdings by Account'!$B$5:$B$84,$A33,'Holdings by Account'!$R$5:$R$84) -> 5112.62 | L33: =IF(J33=0,"",K33/J33) -> 0.95567278 | M33: 0.33746053 | N33: =I33/SUM($I$5:$I$65) -> 0.0080710428 | O33: =SUM($N$5:N33) -> 0.86910774 | P33: =SUMIF('Holdings by Account'!$B$5:$B$84,$A33,'Holdings by Account'!$V$5:$V$84) -> 267.82
A34: GOOG | B34: ALPHABET INC | C34: Individual stock – Communication | D34: Equity | E34: Stock | F34: Communication | G34: Taxable | H34: =SUMIF('Holdings by Account'!$B$5:$B$84,$A34,'Holdings by Account'!$K$5:$K$84) -> 9483.07 | I34: =SUMIF('Holdings by Account'!$B$5:$B$84,$A34,'Holdings by Account'!$P$5:$P$84) -> 10149.17 | J34: =SUMIF('Holdings by Account'!$B$5:$B$84,$A34,'Holdings by Account'!$Q$5:$Q$84) -> 3946.6 | K34: =SUMIF('Holdings by Account'!$B$5:$B$84,$A34,'Holdings by Account'!$R$5:$R$84) -> 6202.57 | L34: =IF(J34=0,"",K34/J34) -> 1.5716237 | M34: 0.068865519 | N34: =I34/SUM($I$5:$I$65) -> 0.0078294217 | O34: =SUM($N$5:N34) -> 0.87693716 | P34: =SUMIF('Holdings by Account'!$B$5:$B$84,$A34,'Holdings by Account'!$V$5:$V$84) -> 26.63
A35: VFFIX | B35: VICTORY PORTFOLIOS | C35: Gov't/MBS income fund | D35: Fixed Income | E35: Fund/ETF | G35: IRA | H35: =SUMIF('Holdings by Account'!$B$5:$B$84,$A35,'Holdings by Account'!$K$5:$K$84) -> 10050.25 | I35: =SUMIF('Holdings by Account'!$B$5:$B$84,$A35,'Holdings by Account'!$P$5:$P$84) -> 10118.7 | J35: =SUMIF('Holdings by Account'!$B$5:$B$84,$A35,'Holdings by Account'!$Q$5:$Q$84) -> 12389.57 | K35: =SUMIF('Holdings by Account'!$B$5:$B$84,$A35,'Holdings by Account'!$R$5:$R$84) -> -2270.87 | L35: =IF(J35=0,"",K35/J35) -> -0.18328885 | M35: -0.023529412 | N35: =I35/SUM($I$5:$I$65) -> 0.0078059161 | O35: =SUM($N$5:N35) -> 0.88474308 | P35: =SUMIF('Holdings by Account'!$B$5:$B$84,$A35,'Holdings by Account'!$V$5:$V$84) -> 554.7
A36: SHLD | B36: GLOBAL X FUNDS | C36: Individual stock – Industrials (Defense ETF) | D36: Equity | E36: Stock | F36: Industrials (Defense ETF) | G36: Taxable | H36: =SUMIF('Holdings by Account'!$B$5:$B$84,$A36,'Holdings by Account'!$K$5:$K$84) -> 0 | I36: =SUMIF('Holdings by Account'!$B$5:$B$84,$A36,'Holdings by Account'!$P$5:$P$84) -> 10113.19 | J36: =SUMIF('Holdings by Account'!$B$5:$B$84,$A36,'Holdings by Account'!$Q$5:$Q$84) -> 10040.19 | K36: =SUMIF('Holdings by Account'!$B$5:$B$84,$A36,'Holdings by Account'!$R$5:$R$84) -> 73 | L36: =IF(J36=0,"",K36/J36) -> 0.0072707787 | N36: =I36/SUM($I$5:$I$65) -> 0.0078016655 | O36: =SUM($N$5:N36) -> 0.89254474 | P36: =SUMIF('Holdings by Account'!$B$5:$B$84,$A36,'Holdings by Account'!$V$5:$V$84) -> 51.43
A37: NEE | B37: NEXTERA ENERGY INC | C37: Individual stock – Utilities | D37: Equity | E37: Stock | F37: Utilities | G37: Joint | H37: =SUMIF('Holdings by Account'!$B$5:$B$84,$A37,'Holdings by Account'!$K$5:$K$84) -> 8909.9 | I37: =SUMIF('Holdings by Account'!$B$5:$B$84,$A37,'Holdings by Account'!$P$5:$P$84) -> 9266.65 | J37: =SUMIF('Holdings by Account'!$B$5:$B$84,$A37,'Holdings by Account'!$Q$5:$Q$84) -> 5000.75 | K37: =SUMIF('Holdings by Account'!$B$5:$B$84,$A37,'Holdings by Account'!$R$5:$R$84) -> 4265.9 | L37: =IF(J37=0,"",K37/J37) -> 0.85305204 | M37: 0.025660189 | N37: =I37/SUM($I$5:$I$65) -> 0.0071486152 | O37: =SUM($N$5:N37) -> 0.89969336 | P37: =SUMIF('Holdings by Account'!$B$5:$B$84,$A37,'Holdings by Account'!$V$5:$V$84) -> 280.57
A38: GD | B38: GENERAL DYNAMICS CORP | C38: Individual stock – Industrials | D38: Equity | E38: Stock | F38: Industrials | G38: Joint | H38: =SUMIF('Holdings by Account'!$B$5:$B$84,$A38,'Holdings by Account'!$K$5:$K$84) -> 7725.17 | I38: =SUMIF('Holdings by Account'!$B$5:$B$84,$A38,'Holdings by Account'!$P$5:$P$84) -> 8631.77 | J38: =SUMIF('Holdings by Account'!$B$5:$B$84,$A38,'Holdings by Account'!$Q$5:$Q$84) -> 4419.91 | K38: =SUMIF('Holdings by Account'!$B$5:$B$84,$A38,'Holdings by Account'!$R$5:$R$84) -> 4211.86 | L38: =IF(J38=0,"",K38/J38) -> 0.95292891 | M38: 0.10304164 | N38: =I38/SUM($I$5:$I$65) -> 0.0066588467 | O38: =SUM($N$5:N38) -> 0.9063522 | P38: =SUMIF('Holdings by Account'!$B$5:$B$84,$A38,'Holdings by Account'!$V$5:$V$84) -> 147.83
A39: CRM | B39: SALESFORCE INC | C39: Individual stock – Technology | D39: Equity | E39: Stock | F39: Technology | G39: Taxable | H39: =SUMIF('Holdings by Account'!$B$5:$B$84,$A39,'Holdings by Account'!$K$5:$K$84) -> 8562.55 | I39: =SUMIF('Holdings by Account'!$B$5:$B$84,$A39,'Holdings by Account'!$P$5:$P$84) -> 8380.76 | J39: =SUMIF('Holdings by Account'!$B$5:$B$84,$A39,'Holdings by Account'!$Q$5:$Q$84) -> 7913.35 | K39: =SUMIF('Holdings by Account'!$B$5:$B$84,$A39,'Holdings by Account'!$R$5:$R$84) -> 467.41 | L39: =IF(J39=0,"",K39/J39) -> 0.059066009 | M39: -0.027820769 | N39: =I39/SUM($I$5:$I$65) -> 0.0064652089 | O39: =SUM($N$5:N39) -> 0.91281741 | P39: =SUMIF('Holdings by Account'!$B$5:$B$84,$A39,'Holdings by Account'!$V$5:$V$84) -> 57.27
A40: CASH | B40: RBC INSURED DEPOSITS | C40: Cash sweep | D40: Cash | E40: Cash | G40: IRA, Taxable, Struct. Notes, Joint | H40: =SUMIF('Holdings by Account'!$B$5:$B$84,$A40,'Holdings by Account'!$K$5:$K$84) -> 37316.92 | I40: =SUMIF('Holdings by Account'!$B$5:$B$84,$A40,'Holdings by Account'!$P$5:$P$84) -> 8269.94 | J40: =SUMIF('Holdings by Account'!$B$5:$B$84,$A40,'Holdings by Account'!$Q$5:$Q$84) -> 8269.94 | K40: =SUMIF('Holdings by Account'!$B$5:$B$84,$A40,'Holdings by Account'!$R$5:$R$84) -> 0 | L40: =IF(J40=0,"",K40/J40) -> 0 | N40: =I40/SUM($I$5:$I$65) -> 0.0063797185 | O40: =SUM($N$5:N40) -> 0.91919713 | P40: =SUMIF('Holdings by Account'!$B$5:$B$84,$A40,'Holdings by Account'!$V$5:$V$84) -> 0
A41: MCD | B41: MCDONALDS CORP | C41: Individual stock – Consumer Disc. | D41: Equity | E41: Stock | F41: Consumer Disc. | G41: Taxable, Joint | H41: =SUMIF('Holdings by Account'!$B$5:$B$84,$A41,'Holdings by Account'!$K$5:$K$84) -> 9424.81 | I41: =SUMIF('Holdings by Account'!$B$5:$B$84,$A41,'Holdings by Account'!$P$5:$P$84) -> 8225.77 | J41: =SUMIF('Holdings by Account'!$B$5:$B$84,$A41,'Holdings by Account'!$Q$5:$Q$84) -> 7646.08 | K41: =SUMIF('Holdings by Account'!$B$5:$B$84,$A41,'Holdings by Account'!$R$5:$R$84) -> 579.69 | L41: =IF(J41=0,"",K41/J41) -> 0.07581532 | M41: -0.13771554 | N41: =I41/SUM($I$5:$I$65) -> 0.0063456443 | O41: =SUM($N$5:N41) -> 0.92554278 | P41: =SUMIF('Holdings by Account'!$B$5:$B$84,$A41,'Holdings by Account'!$V$5:$V$84) -> 232.22
...

Sheet Allocation
A1: Diversification — 8/31/2026 (with 12/31/2025 for comparison)
A3: By asset class
A4: Category | B4: Value 12/31/25 | C4: % 12/31/25 | D4: Value 8/31/26 | E4: % 8/31/26 | F4: Change in weight
A5: Equity | B5: =SUMIF('Holdings by Account'!$F$5:$F$84,$A5,'Holdings by Account'!$K$5:$K$84) -> 807060.67 | C5: =B5/$B$10 -> 0.66712325 | D5: =SUMIF('Holdings by Account'!$F$5:$F$84,$A5,'Holdings by Account'!$P$5:$P$84) -> 939726.65 | E5: =D5/$D$10 -> 0.72493773 | F5: =E5-C5 -> 0.057814474
A6: Fixed Income | B6: =SUMIF('Holdings by Account'!$F$5:$F$84,$A6,'Holdings by Account'!$K$5:$K$84) -> 212158.2 | C6: =B6/$B$10 -> 0.17537178 | D6: =SUMIF('Holdings by Account'!$F$5:$F$84,$A6,'Holdings by Account'!$P$5:$P$84) -> 203906.14 | E6: =D6/$D$10 -> 0.15730027 | F6: =E6-C6 -> -0.018071515
A7: Mixed | B7: =SUMIF('Holdings by Account'!$F$5:$F$84,$A7,'Holdings by Account'!$K$5:$K$84) -> 89570.27 | C7: =B7/$B$10 -> 0.074039552 | D7: =SUMIF('Holdings by Account'!$F$5:$F$84,$A7,'Holdings by Account'!$P$5:$P$84) -> 76719.5 | E7: =D7/$D$10 -> 0.059184083 | F7: =E7-C7 -> -0.014855469
A8: Structured | B8: =SUMIF('Holdings by Account'!$F$5:$F$84,$A8,'Holdings by Account'!$K$5:$K$84) -> 63656.4 | C8: =B8/$B$10 -> 0.052618925 | D8: =SUMIF('Holdings by Account'!$F$5:$F$84,$A8,'Holdings by Account'!$P$5:$P$84) -> 67663.8 | E8: =D8/$D$10 -> 0.052198202 | F8: =E8-C8 -> -0.00042072291
A9: Cash | B9: =SUMIF('Holdings by Account'!$F$5:$F$84,$A9,'Holdings by Account'!$K$5:$K$84) -> 37316.92 | C9: =B9/$B$10 -> 0.030846485 | D9: =SUMIF('Holdings by Account'!$F$5:$F$84,$A9,'Holdings by Account'!$P$5:$P$84) -> 8269.94 | E9: =D9/$D$10 -> 0.0063797185 | F9: =E9-C9 -> -0.024466767
A10: Total | B10: =SUM(B5:B9) -> 1209762.5 | C10: =SUM(C5:C9) -> 1 | D10: =SUM(D5:D9) -> 1296286 | E10: =SUM(E5:E9) -> 1
A12: By vehicle
A13: Category | B13: Value 12/31/25 | C13: % 12/31/25 | D13: Value 8/31/26 | E13: % 8/31/26 | F13: Change in weight
A14: Fund/ETF | B14: =SUMIF('Holdings by Account'!$G$5:$G$84,$A14,'Holdings by Account'!$K$5:$K$84) -> 692754.65 | C14: =B14/$B$18 -> 0.57263692 | D14: =SUMIF('Holdings by Account'!$G$5:$G$84,$A14,'Holdings by Account'!$P$5:$P$84) -> 748109.89 | E14: =D14/$D$18 -> 0.57711791 | F14: =E14-C14 -> 0.0044809935
A15: Stock | B15: =SUMIF('Holdings by Account'!$G$5:$G$84,$A15,'Holdings by Account'!$K$5:$K$84) -> 416034.49 | C15: =B15/$B$18 -> 0.34389767 | D15: =SUMIF('Holdings by Account'!$G$5:$G$84,$A15,'Holdings by Account'!$P$5:$P$84) -> 472242.4 | E15: =D15/$D$18 -> 0.36430417 | F15: =E15-C15 -> 0.020406496
A16: Structured | B16: =SUMIF('Holdings by Account'!$G$5:$G$84,$A16,'Holdings by Account'!$K$5:$K$84) -> 63656.4 | C16: =B16/$B$18 -> 0.052618925 | D16: =SUMIF('Holdings by Account'!$G$5:$G$84,$A16,'Holdings by Account'!$P$5:$P$84) -> 67663.8 | E16: =D16/$D$18 -> 0.052198202 | F16: =E16-C16 -> -0.00042072291
A17: Cash | B17: =SUMIF('Holdings by Account'!$G$5:$G$84,$A17,'Holdings by Account'!$K$5:$K$84) -> 37316.92 | C17: =B17/$B$18 -> 0.030846485 | D17: =SUMIF('Holdings by Account'!$G$5:$G$84,$A17,'Holdings by Account'!$P$5:$P$84) -> 8269.94 | E17: =D17/$D$18 -> 0.0063797185 | F17: =E17-C17 -> -0.024466767
A18: Total | B18: =SUM(B14:B17) -> 1209762.5 | C18: =SUM(C14:C17) -> 1 | D18: =SUM(D14:D17) -> 1296286 | E18: =SUM(E14:E17) -> 1
A20: By classification (stock sector / fund style)
A21: Category | B21: Value 12/31/25 | C21: % 12/31/25 | D21: Value 8/31/26 | E21: % 8/31/26 | F21: Change in weight
A22: Individual stock – Technology | B22: =SUMIF('Holdings by Account'!$E$5:$E$84,$A22,'Holdings by Account'!$K$5:$K$84) -> 148665.45 | C22: =B22/$B$54 -> 0.12288813 | D22: =SUMIF('Holdings by Account'!$E$5:$E$84,$A22,'Holdings by Account'!$P$5:$P$84) -> 163924.29 | E22: =D22/$D$54 -> 0.12645688 | F22: =E22-C22 -> 0.0035687494
A23: Sector fund – Technology | B23: =SUMIF('Holdings by Account'!$E$5:$E$84,$A23,'Holdings by Account'!$K$5:$K$84) -> 104323.35 | C23: =B23/$B$54 -> 0.086234574 | D23: =SUMIF('Holdings by Account'!$E$5:$E$84,$A23,'Holdings by Account'!$P$5:$P$84) -> 142583.32 | E23: =D23/$D$54 -> 0.10999372 | F23: =E23-C23 -> 0.023759144
A24: US Dividend-growth ETF | B24: =SUMIF('Holdings by Account'!$E$5:$E$84,$A24,'Holdings by Account'!$K$5:$K$84) -> 0 | C24: =B24/$B$54 -> 0 | D24: =SUMIF('Holdings by Account'!$E$5:$E$84,$A24,'Holdings by Account'!$P$5:$P$84) -> 116848.76 | E24: =D24/$D$54 -> 0.090141186 | F24: =E24-C24 -> 0.090141186
