Workbook

Sheet Household Summary
A1: Evans household — investable assets by account (401(k)/joint/529 as of 6/30/2026; DB annuity 7/16/2026; Schwab custodial accounts 7/31/2026)
A2: Blue = statement figures; black = formulas. Equity/bond/cash split is a look-through estimate using each fund's published mix (target-date funds) or 100% for single securities.
A4: Account | B4: Owner | C4: Custodian | D4: Type | E4: As of | F4: Value | G4: YTD beginning | H4: YTD contributions | I4: YTD fees (explicit) | J4: YTD gain (value − beg − contrib) | K4: YTD return (simple) | L4: Equity $ | M4: Bonds $ | N4: Cash $ | O4: At Schwab? | P4: Buffered index $
A5: Hot Rod 401(k) — Tommy | B5: Tommy | C5: Equitable (group variable annuity) | D5: 401(k) | E5: 2026-06-30 | F5: 372922.5 | G5: 342163.14 | H5: 10208.3 | I5: 651.63 | J5: =F5-G5-H5 -> 20551.06 | K5: =J5/(G5+0.5*H5) -> 0.059179372 | L5: 192432.9 | M5: 60928.62 | N5: 119053.24 | O5: No | P5: 0
A6: Hot Rod 401(k) — Emma | B6: Emma | C6: Equitable (group variable annuity) | D6: 401(k) | E6: 2026-06-30 | F6: 11872.47 | G6: 10833.32 | H6: 0 | I6: 31.16 | J6: =F6-G6-H6 -> 1039.15 | K6: =J6/(G6+0.5*H6) -> 0.095921657 | L6: 9497.98 | M6: 2374.49 | N6: 0 | O6: No | P6: 0
A7: Joint brokerage (JTTEN TOD) | B7: Tommy & Emma | C7: Equitable Advisors / LPL Financial | D7: Taxable | E7: 2026-06-30 | F7: 55844.92 | G7: 55792.92 | H7: 0 | I7: 0 | J7: =F7-G7-H7 -> 52 | K7: =J7/(G7+0.5*H7) -> 0.0009320179 | L7: 11105.9 | M7: 43976 | N7: 763.02 | O7: No | P7: 0
A8: Sadie custodial Roth IRA | B8: Sadie | C8: Charles Schwab | D8: Roth IRA (minor) | E8: 2026-07-31 | F8: 15090.19 | G8: 14604.31 | H8: 0 | I8: 0 | J8: =F8-G8-H8 -> 485.88 | K8: =J8/(G8+0.5*H8) -> 0.033269631 | L8: 7600.02 | M8: 1071.07 | N8: 6419.1 | O8: Yes | P8: 0
A9: Sadie UTMA | B9: Sadie | C9: Charles Schwab | D9: UTMA (CA) | E9: 2026-07-31 | F9: 6062.34 | G9: 5582.5 | H9: 0 | I9: 0 | J9: =F9-G9-H9 -> 479.84 | K9: =J9/(G9+0.5*H9) -> 0.085954322 | L9: 4537.95 | M9: 0 | N9: 1524.39 | O9: Yes | P9: 0
A10: Wren UTMA | B10: Wren | C10: Charles Schwab | D10: UTMA (CA) | E10: 2026-07-31 | F10: 5777.73 | G10: 5364.73 | H10: 0 | I10: 0 | J10: =F10-G10-H10 -> 413 | K10: =J10/(G10+0.5*H10) -> 0.076984303 | L10: 3878.86 | M10: 292.11 | N10: 1606.76 | O10: Yes | P10: 0
A11: Evans Group DB plan — SCS PLUS annuity | B11: Evans Group Home Loans (Tommy annuitant) | C11: Equitable (index-linked annuity) | D11: Defined benefit plan | E11: 2026-07-16 | F11: 737594.39 | J11: n/a | K11: n/a | L11: 0 | M11: 0 | N11: 0 | O11: No | P11: 737594.39
A12: my529 — Wren | B12: Tommy (bene. Wren) | C12: my529 (Utah) | D12: 529 | E12: 2026-06-30 | F12: 57240.39 | G12: 52128.12 | H12: 1200 | J12: =F12-G12-H12 -> 3912.27 | K12: =J12/(G12+0.5*H12) -> 0.074197032 | L12: 31482.21 | M12: 25758.18 | N12: 0 | O12: No | P12: 0
A13: TOTAL | F13: =SUM(F5:F12) -> 1262404.9 | G13: =SUM(G5:G12) -> 486469.04 | H13: =SUM(H5:H12) -> 11408.3 | I13: =SUM(I5:I12) -> 682.79 | J13: =SUM(J5:J12) -> 26933.2 | K13: ex-DB | L13: =SUM(L5:L12) -> 260535.82 | M13: =SUM(M5:M12) -> 134400.47 | N13: =SUM(N5:N12) -> 129366.51 | P13: =SUM(P5:P12) -> 737594.39
A15: Allocation look-through
A16: Equity funds & stocks | B16: =L13 -> 260535.82 | C16: =B16/$F$13 -> 0.20638055
A17: Buffered index segments (DB annuity) | B17: =P13 -> 737594.39 | C17: =B17/$F$13 -> 0.58427718
A18: Bonds / stable value | B18: =M13 -> 134400.47 | C18: =B18/$F$13 -> 0.10646383
A19: Cash & money market | B19: =N13 -> 129366.51 | C19: =B19/$F$13 -> 0.10247624
A21: Where the money sits
A22: At Equitable / LPL (to be moved) | B22: =SUMIF(C5:C12,"*Equitable*",F5:F12) -> 1178234.3 | C22: =B22/$F$13 -> 0.93332516
A23: Already at Schwab | B23: =SUMIF(O5:O12,"Yes",F5:F12) -> 26930.26 | C23: =B23/$F$13 -> 0.021332505
A24: my529 (stays) | B24: =SUMIF(D5:D12,"529",F5:F12) -> 57240.39 | C24: =B24/$F$13 -> 0.045342337
A25: Idle cash earning 0.01% (all accounts) | B25: 9479.86
A27: Not valued (documents give no balance): Prudential flexible-premium life policy V2 668 056 ($500/yr planned premium); home at 973 Begonia Ave (mortgage $467,835.72 at 2.75%).

Sheet Assumptions
A1: Assumptions and external inputs (blue = input; edit here and the Cost sheet recalculates)
A3: Input | B3: Value | C3: Unit | D3: Source / note
A4: TRP Retirement R-class expense ratio | B4: 1.08 | C4: %/yr | D4: T. Rowe Price Retirement 2035 R fact sheet 6/30/2026 (RRTPX 1.08%; R class carries a 0.50% 12b-1). Verify current prospectus.
A5: Schwab Target 2035 Index (SWYFX) expense ratio | B5: 0.08 | C5: %/yr | D5: Schwab Asset Management; approx — verify.
A6: Money-market yield available at Schwab (SWVXX) | B6: 3.7 | C6: %/yr | D6: Approx 7-day yield; 3-mo T-bill 3.83% on 8/31/26 per Merrill statement. Verify.
A7: Equitable Guaranteed Interest Option rate | B7: 2 | C7: %/yr | D7: Sponsor report: 2.00% in effect until 7/31/2026.
A8: Sweep rate (LPL ICA / Schwab Bank Sweep) | B8: 0.01 | C8: %/yr | D8: Printed on statements.
A9: LPL outgoing ACAT fee | B9: 125 | C9: $/acct | D9: LPL FS07 brokerage fee schedule eff. 1/1/2026: $125 per account.
A10: LPL brokerage maintenance fee | B10: 100 | C10: $/yr | D10: LPL FS07: $100/yr; statement shows $0 fees YTD so may be waived/paid elsewhere — verify.
A11: Schwab Individual 401(k) fees | B11: 0 | C11: $/yr | D11: schwab.com: no fee to open or maintain; $0 online ETF/stock commissions; no participant loans; owner + spouse only.
A12: Schwab Personal Defined Benefit Plan setup | B12: 2250 | C12: $ | D12: schwab.com: from $2,250 plus annual service fees; designed for $90k+/yr contributions.
A13: Q2 2026 asset charge, whole plan | B13: 351.66 | C13: $/qtr | D13: Sponsor report 'Fees' line; participant statements show ASSET CHARGE $335.75 + $15.91.

Sheet Holdings
A1: Every holding across the eight valued accounts
A3: Account | B3: Holding | C3: Kind | D3: Value | E3: % of account | F3: % of household | G3: Equity % | H3: Bond % | I3: Cash %
A4: Hot Rod 401(k) — Tommy | B4: T. Rowe Price Retirement 2035 R | C4: target-date fund | D4: 253869.26 | E4: =D4/372922.5 -> 0.68075608 | F4: =D4/'Household Summary'!$F$13 -> 0.20109971 | G4: 0.758 | H4: 0.24 | I4: 0
A5: Hot Rod 401(k) — Tommy | B5: Guaranteed Interest Option (2.00%) | C5: stable value | D5: 119053.24 | E5: =D5/372922.5 -> 0.31924392 | F5: =D5/'Household Summary'!$F$13 -> 0.094306698 | G5: 0 | H5: 0 | I5: 1
A6: Hot Rod 401(k) — Emma | B6: T. Rowe Price Retirement 2040 R | C6: target-date fund | D6: 11872.47 | E6: =D6/11872.47 -> 1 | F6: =D6/'Household Summary'!$F$13 -> 0.0094046448 | G6: 0.8 | H6: 0.2 | I6: 0
A7: Joint brokerage (JTTEN TOD) | B7: US Treasury STRIP 8/15/2029 (zero coupon) | C7: Treasury zero | D7: 43976 | E7: =D7/55844.92 -> 0.78746643 | F7: =D7/'Household Summary'!$F$13 -> 0.034835098 | G7: 0 | H7: 1 | I7: 0
A8: Joint brokerage (JTTEN TOD) | B8: SPCX — Space Exploration Technologies Cl A | C8: single stock | D8: 11105.9 | E8: =D8/55844.92 -> 0.19887037 | F8: =D8/'Household Summary'!$F$13 -> 0.0087974149 | G8: 1 | H8: 0 | I8: 0
A9: Joint brokerage (JTTEN TOD) | B9: LPL Insured Cash (0.01%) | C9: cash | D9: 763.02 | E9: =D9/55844.92 -> 0.013663194 | F9: =D9/'Household Summary'!$F$13 -> 0.00060441779 | G9: 0 | H9: 0 | I9: 1
A10: Sadie custodial Roth IRA | B10: ACWI — iShares MSCI ACWI | C10: global equity ETF | D10: 6882.92 | E10: =D10/15090.19 -> 0.45611884 | F10: =D10/'Household Summary'!$F$13 -> 0.0054522284 | G10: 1 | H10: 0 | I10: 0
A11: Sadie custodial Roth IRA | B11: AGG — iShares Core US Aggregate Bond | C11: bond ETF | D11: 1071.07 | E11: =D11/15090.19 -> 0.0709779 | F11: =D11/'Household Summary'!$F$13 -> 0.00084843617 | G11: 0 | H11: 1 | I11: 0
A12: Sadie custodial Roth IRA | B12: NFLX — Netflix | C12: single stock | D12: 717.1 | E12: =D12/15090.19 -> 0.047520939 | F12: =D12/'Household Summary'!$F$13 -> 0.00056804278 | G12: 1 | H12: 0 | I12: 0
A13: Sadie custodial Roth IRA | B13: Schwab Bank Sweep (0.01%) | C13: cash | D13: 6419.1 | E13: =D13/15090.19 -> 0.42538232 | F13: =D13/'Household Summary'!$F$13 -> 0.0050848185 | G13: 0 | H13: 0 | I13: 1
A14: Sadie UTMA | B14: ACWI | C14: global equity ETF | D14: 3128.6 | E14: =D14/6062.34 -> 0.51607135 | F14: =D14/'Household Summary'!$F$13 -> 0.0024782856 | G14: 1 | H14: 0 | I14: 0
A15: Sadie UTMA | B15: QQQ — Invesco Nasdaq-100 | C15: US growth ETF | D15: 1409.35 | E15: =D15/6062.34 -> 0.23247624 | F15: =D15/'Household Summary'!$F$13 -> 0.0011164009 | G15: 1 | H15: 0 | I15: 0
A16: Sadie UTMA | B16: SWVXX money fund | C16: money market | D16: 365.65 | E16: =D16/6062.34 -> 0.060314994 | F16: =D16/'Household Summary'!$F$13 -> 0.00028964557 | G16: 0 | H16: 0 | I16: 1
A17: Sadie UTMA | B17: Schwab Bank Sweep (0.01%) | C17: cash | D17: 1158.74 | E17: =D17/6062.34 -> 0.19113742 | F17: =D17/'Household Summary'!$F$13 -> 0.00091788298 | G17: 0 | H17: 0 | I17: 1
A18: Wren UTMA | B18: ACWI | C18: global equity ETF | D18: 2502.88 | E18: =D18/5777.73 -> 0.43319435 | F18: =D18/'Household Summary'!$F$13 -> 0.0019826285 | G18: 1 | H18: 0 | I18: 0
A19: Wren UTMA | B19: QQQ | C19: US growth ETF | D19: 1375.98 | E19: =D19/5777.73 -> 0.23815235 | F19: =D19/'Household Summary'!$F$13 -> 0.0010899672 | G19: 1 | H19: 0 | I19: 0
A20: Wren UTMA | B20: AGG | C20: bond ETF | D20: 292.11 | E20: =D20/5777.73 -> 0.050557918 | F20: =D20/'Household Summary'!$F$13 -> 0.00023139168 | G20: 0 | H20: 1 | I20: 0
A21: Wren UTMA | B21: SWVXX money fund | C21: money market | D21: 467.76 | E21: =D21/5777.73 -> 0.080959131 | F21: =D21/'Household Summary'!$F$13 -> 0.00037053087 | G21: 0 | H21: 0 | I21: 1
A22: Wren UTMA | B22: Schwab Bank Sweep (0.01%) | C22: cash | D22: 1139 | E22: =D22/5777.73 -> 0.19713625 | F22: =D22/'Household Summary'!$F$13 -> 0.00090224616 | G22: 0 | H22: 0 | I22: 1
A23: Evans Group DB plan — SCS PLUS annuity | B23: S&P 500 buffered segments | C23: buffered index segment | D23: 334870.81 | E23: =D23/737594.39 -> 0.45400401 | F23: =D23/'Household Summary'!$F$13 -> 0.26526418 | G23: 1 | H23: 0 | I23: 0
A24: Evans Group DB plan — SCS PLUS annuity | B24: Russell 2000 buffered segments | C24: buffered index segment | D24: 174941.8 | E24: =D24/737594.39 -> 0.23717886 | F24: =D24/'Household Summary'!$F$13 -> 0.1385782 | G24: 1 | H24: 0 | I24: 0
A25: Evans Group DB plan — SCS PLUS annuity | B25: MSCI EAFE buffered segments | C25: buffered index segment | D25: 137494.61 | E25: =D25/737594.39 -> 0.18640951 | F25: =D25/'Household Summary'!$F$13 -> 0.10891482 | G25: 1 | H25: 0 | I25: 0
A26: Evans Group DB plan — SCS PLUS annuity | B26: NASDAQ 100 buffered segments | C26: buffered index segment | D26: 68818.96 | E26: =D26/737594.39 -> 0.093301903 | F26: =D26/'Household Summary'!$F$13 -> 0.054514172 | G26: 1 | H26: 0 | I26: 0
A27: Evans Group DB plan — SCS PLUS annuity | B27: MSCI EM buffered segments | C27: buffered index segment | D27: 21468.21 | E27: =D27/737594.39 -> 0.029105712 | F27: =D27/'Household Summary'!$F$13 -> 0.017005803 | G27: 1 | H27: 0 | I27: 0
A28: my529 — Wren | B28: Target Enrollment 2032/2033 (UTAJX) | C28: age-based 529 portfolio | D28: 57240.39 | E28: =D28/57240.39 -> 1 | F28: =D28/'Household Summary'!$F$13 -> 0.045342337 | G28: 0.55 | H28: 0.45 | I28: 0
A29: TOTAL | D29: =SUM(D4:D28) -> 1262404.9 | F29: =SUM(F4:F28) -> 1

Sheet Cost Analysis
A1: What the Equitable 401(k) costs today vs. the same money at Schwab (annual run-rate)
A2: Explicit costs come from the statements; embedded fund expenses and the cash/GIO opportunity cost use the Assumptions sheet. Kids' Schwab accounts, the joint LPL account and my529 show $0 explicit fees.
A4: Line | B4: Basis ($) | C4: Rate | D4: Annual cost ($) | E4: Note
A5: 401(k) variable-fund balance (TRP 2035 R + 2040 R) | B5: 265741.73 | E5: Sponsor report 6/30/2026
A6: 401(k) Guaranteed Interest Option balance | B6: 119053.24 | E6: Sponsor report 6/30/2026
A7: Equitable asset charge (explicit, on variable funds) | B7: =B5 -> 265741.73 | C7: =Assumptions!$B$13*4/B5 -> 0.0052932597 | D7: =B7*C7 -> 1406.64 | E7: Q2 fee ×4; charged only on variable funds
A8: T. Rowe Price R-class fund expenses (embedded) | B8: =B5 -> 265741.73 | C8: =Assumptions!$B$4/100 -> 0.0108 | D8: =B8*C8 -> 2870.0107 | E8: Netted out of the unit value; never appears as a line item
A9: GIO opportunity cost vs. a money-market fund | B9: =B6 -> 119053.24 | C9: =(Assumptions!$B$6-Assumptions!$B$7)/100 -> 0.017 | D9: =B9*C9 -> 2023.9051 | E9: 2.00% guaranteed vs ~3.7% available; not a fee, but real
A10: Idle sweep cash at 0.01% (joint + 3 Schwab custodial accounts) | B10: 9479.86 | C10: =(Assumptions!$B$6-Assumptions!$B$8)/100 -> 0.0369 | D10: =B10*C10 -> 349.80683 | E10: Fixable today inside Schwab by buying SWVXX
A11: Total annual cost + drag, as structured today | C11: =D11/(B5+B6) -> 0.017282873 | D11: =SUM(D7:D10) -> 6650.3626 | E11: as % of 401(k) assets
A13: Same balances at Schwab
A14: Schwab Individual 401(k) plan/account fee | B14: =B5+B6 -> 384794.97 | C14: 0 | D14: =Assumptions!$B$11 -> 0 | E14: No setup or maintenance fee
A15: Index target-date fund (e.g. Schwab Target 2035 Index) on the variable balance | B15: =B5 -> 265741.73 | C15: =Assumptions!$B$5/100 -> 0.0008 | D15: =B15*C15 -> 212.59338
A16: Money-market / Treasury bills on the GIO balance (drag vs. best available = 0) | B16: =B6 -> 119053.24 | C16: 0 | D16: 0
A17: Idle cash moved to SWVXX (drag = 0) | B17: =B10 -> 9479.86 | C17: 0 | D17: 0
A18: Total annual cost + drag at Schwab | C18: =D18/(B5+B6) -> 0.00055248483 | D18: =SUM(D14:D17) -> 212.59338
A20: Annual saving | C20: =D20/(B5+B6) -> 0.016730388 | D20: =D11-D18 -> 6437.7692
A21: One-time costs of moving | D21: =Assumptions!$B$9 -> 125 | E21: LPL ACAT on the joint account. Equitable group-annuity contingent withdrawal charge on plan termination: NOT DISCLOSED on the pages provided — obtain before acting.
A22: Ten-year value of the saving (no growth, no compounding) | D22: =D20*10 -> 64377.692
A24: Ten-year projection of the 401(k) at 6% gross, current structure vs. Schwab structure
A25: Year | B25: Current structure (net of cost+drag) | C25: Schwab structure | D25: Difference
A26: 0 | B26: =B5+B6 -> 384794.97 | C26: =B5+B6 -> 384794.97 | D26: =C26-B26 -> 0
A27: 1 | B27: =B26*(1+0.06-$C$11) -> 401232.31 | C27: =C26*(1+0.06-$C$18) -> 407670.07 | D27: =C27-B27 -> 6437.7692
A28: 2 | B28: =B27*(1+0.06-$C$11) -> 418371.8 | C28: =C27*(1+0.06-$C$18) -> 431905.05 | D28: =C28-B28 -> 13533.251
A29: 3 | B29: =B28*(1+0.06-$C$11) -> 436243.44 | C29: =C28*(1+0.06-$C$18) -> 457580.73 | D29: =C29-B29 -> 21337.292
A30: 4 | B30: =B29*(1+0.06-$C$11) -> 454878.5 | C30: =C29*(1+0.06-$C$18) -> 484782.77 | D30: =C30-B30 -> 29904.263
A31: 5 | B31: =B30*(1+0.06-$C$11) -> 474309.61 | C31: =C30*(1+0.06-$C$18) -> 513601.9 | D31: =C31-B31 -> 39292.291
A32: 6 | B32: =B31*(1+0.06-$C$11) -> 494570.75 | C32: =C31*(1+0.06-$C$18) -> 544134.25 | D32: =C32-B32 -> 49563.503
A33: 7 | B33: =B32*(1+0.06-$C$11) -> 515697.39 | C33: =C32*(1+0.06-$C$18) -> 576481.68 | D33: =C33-B33 -> 60784.291
A34: 8 | B34: =B33*(1+0.06-$C$11) -> 537726.5 | C34: =C33*(1+0.06-$C$18) -> 610752.09 | D34: =C34-B34 -> 73025.584
A35: 9 | B35: =B34*(1+0.06-$C$11) -> 560696.64 | C35: =C34*(1+0.06-$C$18) -> 647059.78 | D35: =C35-B35 -> 86363.147
A36: 10 | B36: =B35*(1+0.06-$C$11) -> 584647.98 | C36: =C35*(1+0.06-$C$18) -> 685525.88 | D36: =C36-B36 -> 100877.89
A37: 6% gross return is an ASSUMPTION for illustration only; contributions ignored.

Sheet Schwab Migration Plan
A1: Account-by-account plan to consolidate at Charles Schwab
A3: # | B3: Account | C3: Value | D3: Recommended Schwab destination | E3: Method | F3: Tax effect | G3: Cost / friction | H3: Pre-conditions & open items | I3: Priority
A4: 1 | B4: Hot Rod 401(k) — Tommy + Emma | C4: =384794.97 -> 384794.97 | D4: Schwab Individual 401(k) (traditional + Roth) if the company has no employees other than Tommy and Emma; otherwise a low-cost open-architecture 401(k) provider with Schwab as custodian | E4: Adopt Schwab plan → terminate Equitable contract → direct plan-to-plan rollover (or, without terminating, roll the $108,707 'Rollover' source to a Schwab Rollover IRA if the plan permits in-service distribution of rollover money) | F4: None if done as a direct rollover | G4: Equitable contingent withdrawal charge on the group annuity (schedule not on statements); GIO transfer restriction currently waived — move GIO money first; Schwab I-401(k) does not allow loans | H4: Confirm employee census (Emma is the only other participant); obtain Equitable contract fee/CWC schedule; confirm plan document allows in-service rollover-source distributions; file final Form 5500 on termination | I4: 1
A5: 2 | B5: Evans Group DB plan — SCS PLUS annuity | C5: =737594.39 -> 737594.39 | D5: Schwab-custodied DB plan (Schwab Personal Defined Benefit Plan, or existing TPA with a Schwab company retirement account); or terminate and roll to a Schwab IRA | E5: Now: switch maturity instructions to EQ/Money Market so maturing segments stop re-locking; from 2/10/2027 (withdrawal charge 0%): trustee-to-trustee transfer of cash + matured segments; decide 6-year segments individually | F5: None if transferred/rolled; plan termination needs actuary/IRS steps | G5: 3% withdrawal charge until 2/9/2027 (~$22,128 today); 6-year segments exited early get interim value with no buffer; Schwab PDB setup from $2,250 | H5: Get actuarial report, funding target and contribution schedule from TPA; confirm free-withdrawal amount; decide whether the business keeps funding a DB plan | I5: 1
A6: 3 | B6: Joint brokerage (LPL x1858) | C6: =55844.92 -> 55844.92 | D6: Schwab One joint TOD brokerage | E6: ACAT transfer in kind (STRIP, SPCX and cash all transfer) | F6: None on transfer; selling the STRIP would realize a small loss, SPCX a small short-term gain | G6: $125 LPL ACAT fee; nothing at Schwab | H6: Decide whether to keep the 2029 STRIP to maturity (≈4.2% yield to maturity) and whether SPCX belongs in an 'income' account; move cash to SWVXX | I6: 1
A7: 4 | B7: Sadie custodial Roth IRA | C7: =15090.19 -> 15090.19 | D7: Already at Schwab — no move | E7: Invest the $6,419 idle cash; add 2026 contribution if Sadie has earned income | F7: — | G7: — | H7: Roth contribution requires the child's earned income up to $7,000 | I7: 3
A8: 5 | B8: Sadie UTMA / Wren UTMA | C8: =11840.07 -> 11840.07 | D8: Already at Schwab — no move | E8: Sweep bank cash ($1,159 / $1,139) into SWVXX or ETFs | F8: Kiddie-tax rules apply above $2,700 unearned income (2026) | G8: — | H8: Consider whether new gifts should go to 529 instead of UTMA (control, financial-aid treatment) | I8: 3
A9: 6 | B9: my529 — Wren | C9: =57240.39 -> 57240.39 | D9: Keep at my529 (0.08% admin + index underlying); Schwab has no house 529 | E9: No action | F9: — | G9: — | H9: Sadie has no 529 on file — consider opening one | I9: 3
A10: 7 | B10: Prudential flexible-premium life (VUL?) | C10: unknown | D10: Not a Schwab product; review separately | E10: Request in-force illustration and annual statement | F10: — | G10: — | H10: Know cash value, cost of insurance, and whether the $500/yr premium keeps it in force | I10: 2
A11: 8 | B11: Mortgage 2.75% (RoundPoint) | C11: =-467835.72 -> -467835.72 | D11: Keep — do not prepay | E11: — | F11: Interest deductible if itemizing | G11: — | H11: ~24 years remaining; rate far below current money-market yields | I11: —

Sheet DB Plan Annuity
A1: Evans Group DB plan — Equitable Structured Capital Strategies PLUS QP annuity, contract 321 012 247 (Segment Activity Report of 7/16/2026)
A2: Total Annuity Account Value $737,594.39, 100% in 129 index-linked segments (interim values). No contributions, fees, surrender value or plan-funding data are on the report.
A4: By index
A5: Index | B5: Value | C5: % of annuity
A6: S&P 500 | B6: 334870.81 | C6: =B6/$B$11 -> 0.45400401
A7: Russell 2000 | B7: 174941.8 | C7: =B7/$B$11 -> 0.23717886
A8: MSCI EAFE ETF | B8: 137494.61 | C8: =B8/$B$11 -> 0.18640951
A9: NASDAQ 100 | B9: 68818.96 | C9: =B9/$B$11 -> 0.093301903
A10: MSCI EM | B10: 21468.21 | C10: =B10/$B$11 -> 0.029105712
A11: Total | B11: =SUM(B6:B10) -> 737594.39
A13: By segment term
A14: Term | B14: Value | C14: %
A15: 1-year segments | B15: 276082.87 | C15: =B15/$B$17 -> 0.37430175
A16: 6-year segments | B16: 461511.52 | C16: =B16/$B$17 -> 0.62569825
A17: Total | B17: =SUM(B15:B16) -> 737594.39
A19: By segment type
A20: Type | B20: Value | C20: %
A21: Standard | B21: 371008.77 | C21: =B21/$B$26 -> 0.50299836
A22: Dual Direction | B22: 226496.86 | C22: =B22/$B$26 -> 0.30707508
A23: Step Up | B23: 54611.91 | C23: =B23/$B$26 -> 0.074040571
A24: Annual Lock | B24: 51504.15 | C24: =B24/$B$26 -> 0.069827199
A25: Enhanced Upside | B25: 33972.7 | C25: =B25/$B$26 -> 0.046058783
A26: Total | B26: =SUM(B21:B25) -> 737594.39
A28: Value by maturity year (interim values)
A29: Maturity year | B29: Value | C29: Cumulative | D29: Note
A30: 2026 | B30: 134832.51 | C30: =SUM($B$30:B30) -> 134832.51 | D30: 1-year segments; movable at maturity
A31: 2027 | B31: 264801.15 | C31: =SUM($B$30:B31) -> 399633.66 | D31: 1-year segments; movable at maturity
A32: 2028 | B32: 82762.56 | C32: =SUM($B$30:B32) -> 482396.22 | D32: 6-year segments; early exit = interim value (no buffer)
A33: 2029 | B33: 214316.83 | C33: =SUM($B$30:B33) -> 696713.05 | D33: 6-year segments; early exit = interim value (no buffer)
A34: 2030 | B34: 21042.91 | C34: =SUM($B$30:B34) -> 717755.96 | D34: 6-year segments; early exit = interim value (no buffer)
A35: 2031 | B35: 19838.43 | C35: =SUM($B$30:B35) -> 737594.39 | D35: 6-year segments; early exit = interim value (no buffer)
A36: Total | B36: =SUM(B30:B35) -> 737594.39
A38: Withdrawal charge (SCS PLUS: 6/6/5/5/4/3/0% by contract year; contract date 2/10/2021)
A39: Charge if surrendered before 2/10/2027 | B39: 0.03 | C39: =B39*737594.39 -> 22127.832
A40: Charge from 2/10/2027 | B40: 0
A42: Annual-lock segment-years printed on the report: index price return vs. return credited
A43: Segment | B43: Year | C43: Cap % | D43: Index return % | E43: Credited % | F43: Cap cost (pts) | G43: Buffer benefit (pts)
A44: S&P 500 Annual Lock 6 Year -10% Buffer Sep 19 | B44: 2023 | C44: 0.155 | D44: 0.2975 | E44: 0.155 | F44: =MAX(D44-C44,0) -> 0.1425 | G44: =IF(D44<0,E44-D44,0) -> 0
A45: S&P 500 Annual Lock 6 Year -10% Buffer Sep 19 | B45: 2024 | C45: 0.155 | D45: 0.1748 | E45: 0.155 | F45: =MAX(D45-C45,0) -> 0.0198 | G45: =IF(D45<0,E45-D45,0) -> 0
A46: S&P 500 Annual Lock 6 Year -10% Buffer Oct 16 | B46: 2024 | C46: 0.07 | D46: 0.142 | E46: 0.07 | F46: =MAX(D46-C46,0) -> 0.072 | G46: =IF(D46<0,E46-D46,0) -> 0
...

Sheet Sources
A1: Documents used (all scanned PDFs in WAN\T-V, read page by page)
A3: TOMMY 401k 202606.pdf | B3: Equitable Retirement Account Update Q2 2026, participant 219232842 — pages 1-3 and 8 of 8
A4: EMMA 401k 202606.pdf | B4: Equitable Retirement Account Update Q2 2026, participant 220249613
A5: EVANS 401k sponsor report 202606.pdf | B5: Equitable Plan Sponsor Update Q2 2026, contract 693006 (fund line-up performance, plan totals)
A6: JOINT Equitable x1858.pdf | B6: Equitable Advisors / LPL brokerage statement Q2 2026, pages 1-5 of 12
A7: SADIE Roth IRA x450.pdf / SADIE UTMA x444.pdf / WREN UTMA x504.pdf | B7: Schwab statements July 2026
A8: Tommy my529 202606.pdf | B8: my529 quarterly statement Q2 2026, page 1 of 2
A9: Evans Group DB Maturity Letter 202608.pdf | B9: Equitable SCS PLUS QP segment maturity notice 8/3/2026 (no values)
A10: TOMMY DBplan 202606.pdf | B10: Equitable SCS PLUS QP Segment Activity Report 7/16/2026, contract 321 012 247 — 129 segments, total $737,594.39 (added in v2)
A11: HOME RoundPoint Mortgage - Aug 1, 2026.pdf | B11: Mortgage billing statement 7/6/2026
A12: Tommy Prudential Pay request 20260819.pdf | B12: Prudential planned-premium payment notice (not a bill)
